Workbook

Sheet 月度汇总
A1: 类别 | B1: 项目 | C1: 月度汇总 | D1: 1日 | E1: 2日 | F1: 3日 | G1: 4日 | H1: 5日 | I1: 6日 | J1: 7日 | K1: 8日 | L1: 9日 | M1: 10日 | N1: 11日 | O1: 12日 | P1: 13日 | Q1: 14日 | R1: 15日 | S1: 16日 | T1: 17日 | U1: 18日 | V1: 19日 | W1: 20日 | X1: 21日 | Y1: 22日 | Z1: 23日 | AA1: 24日 | AB1: 25日 | AC1: 26日 | AD1: 27日 | AE1: 28日 | AF1: 29日 | AG1: 30日 | AH1: 31日
B2: 实际用电量（MWh） | C2: =SUM(D2:AH2) -> 14040.644 | D2: =SUMIF('计算过程-数据汇总'!$A:$A,'维护-日期'!B2,'计算过程-数据汇总'!$C:$C) -> 458.396 | E2: =SUMIF('计算过程-数据汇总'!$A:$A,'维护-日期'!C2,'计算过程-数据汇总'!$C:$C) -> 458.396 | F2: =SUMIF('计算过程-数据汇总'!$A:$A,'维护-日期'!D2,'计算过程-数据汇总'!$C:$C) -> 458.396 | G2: =SUMIF('计算过程-数据汇总'!$A:$A,'维护-日期'!E2,'计算过程-数据汇总'!$C:$C) -> 458.396 | H2: =SUMIF('计算过程-数据汇总'!$A:$A,'维护-日期'!F2,'计算过程-数据汇总'!$C:$C) -> 437.192 | I2: =SUMIF('计算过程-数据汇总'!$A:$A,'维护-日期'!G2,'计算过程-数据汇总'!$C:$C) -> 437.192 | J2: =SUMIF('计算过程-数据汇总'!$A:$A,'维护-日期'!H2,'计算过程-数据汇总'!$C:$C) -> 458.396 | K2: =SUMIF('计算过程-数据汇总'!$A:$A,'维护-日期'!I2,'计算过程-数据汇总'!$C:$C) -> 458.396 | ... AH2: =SUMIF('计算过程-数据汇总'!$A:$A,'维护-日期'!AF2,'计算过程-数据汇总'!$C:$C) -> 458.396
B3: 预测用电量（MWh） | C3: =SUM(D3:AH3) -> 14040.644 | D3: =SUMIF('计算过程-数据汇总'!$A:$A,'维护-日期'!B2,'计算过程-数据汇总'!$D:$D) -> 458.396 | E3: =SUMIF('计算过程-数据汇总'!$A:$A,'维护-日期'!C2,'计算过程-数据汇总'!$D:$D) -> 458.396 | F3: =SUMIF('计算过程-数据汇总'!$A:$A,'维护-日期'!D2,'计算过程-数据汇总'!$D:$D) -> 458.396 | G3: =SUMIF('计算过程-数据汇总'!$A:$A,'维护-日期'!E2,'计算过程-数据汇总'!$D:$D) -> 458.396 | H3: =SUMIF('计算过程-数据汇总'!$A:$A,'维护-日期'!F2,'计算过程-数据汇总'!$D:$D) -> 437.192 | I3: =SUMIF('计算过程-数据汇总'!$A:$A,'维护-日期'!G2,'计算过程-数据汇总'!$D:$D) -> 437.192 | J3: =SUMIF('计算过程-数据汇总'!$A:$A,'维护-日期'!H2,'计算过程-数据汇总'!$D:$D) -> 458.396 | K3: =SUMIF('计算过程-数据汇总'!$A:$A,'维护-日期'!I2,'计算过程-数据汇总'!$D:$D) -> 458.396 | ... AH3: =SUMIF('计算过程-数据汇总'!$A:$A,'维护-日期'!AF2,'计算过程-数据汇总'!$D:$D) -> 458.396
B4: 电量波动（%） | C4: =C2/C3-1 -> 0 | D4: =D2/D3-1 -> 0 | E4: =E2/E3-1 -> 0 | F4: =F2/F3-1 -> 0 | G4: =G2/G3-1 -> 0 | H4: =H2/H3-1 -> 0 | I4: =I2/I3-1 -> 0 | J4: =J2/J3-1 -> 0 | ... AH4: =AH2/AH3-1 -> 0
B5: 结算电价（元/MWh） | C5: =C6/C2 -> 372 | D5: =D6/D2 -> 372 | E5: =E6/E2 -> 372 | F5: =F6/F2 -> 372 | G5: =G6/G2 -> 372 | H5: =H6/H2 -> 372 | I5: =I6/I2 -> 372 | J5: =J6/J2 -> 372 | ... AH5: =AH6/AH2 -> 372
B6: 结算电费（元） | C6: =SUM(C7:C12) -> 5223119.6 | D6: =SUM(D7:D12) -> 170523.31 | E6: =SUM(E7:E12) -> 170523.31 | F6: =SUM(F7:F12) -> 170523.31 | G6: =SUM(G7:G12) -> 170523.31 | H6: =SUM(H7:H12) -> 162635.42 | I6: =SUM(I7:I12) -> 162635.42 | J6: =SUM(J7:J12) -> 170523.31 | ... AH6: =SUM(AH7:AH12) -> 170523.31
B7: 交易电费 | C7: =SUM(D7:AH7) -> 5223119.6 | D7: =D18+D9+D19+D22 -> 170523.31 | E7: =E18+E9+E19+E22 -> 170523.31 | F7: =F18+F9+F19+F22 -> 170523.31 | G7: =G18+G9+G19+G22 -> 170523.31 | H7: =H18+H9+H19+H22 -> 162635.42 | I7: =I18+I9+I19+I22 -> 162635.42 | J7: =J18+J9+J19+J22 -> 170523.31 | K7: =K18+K9+K19+K22 -> 170523.31 | ... AH7: =AH18+AH9+AH19+AH22 -> 170523.31
B8: ='计算过程-数据汇总'!Q1 -> 日前偏差超额回收（日考核） | C8: =SUM(D8:AH8) -> 0 | D8: =SUMIF('计算过程-数据汇总'!$A:$A,'维护-日期'!B2,'计算过程-数据汇总'!$Q:$Q) -> 0 | E8: =SUMIF('计算过程-数据汇总'!$A:$A,'维护-日期'!C2,'计算过程-数据汇总'!$Q:$Q) -> 0 | F8: =SUMIF('计算过程-数据汇总'!$A:$A,'维护-日期'!D2,'计算过程-数据汇总'!$Q:$Q) -> 0 | G8: =SUMIF('计算过程-数据汇总'!$A:$A,'维护-日期'!E2,'计算过程-数据汇总'!$Q:$Q) -> 0 | H8: =SUMIF('计算过程-数据汇总'!$A:$A,'维护-日期'!F2,'计算过程-数据汇总'!$Q:$Q) -> 0 | I8: =SUMIF('计算过程-数据汇总'!$A:$A,'维护-日期'!G2,'计算过程-数据汇总'!$Q:$Q) -> 0 | J8: =SUMIF('计算过程-数据汇总'!$A:$A,'维护-日期'!H2,'计算过程-数据汇总'!$Q:$Q) -> 0 | K8: =SUMIF('计算过程-数据汇总'!$A:$A,'维护-日期'!I2,'计算过程-数据汇总'!$Q:$Q) -> 0 | ... AH8: =SUMIF('计算过程-数据汇总'!$A:$A,'维护-日期'!AF2,'计算过程-数据汇总'!$Q:$Q) -> 0
B9: 省间现货电费 | C9: =SUM(D9:AH9) -> 0 | D9: =SUMIF('计算过程-数据汇总'!$A:$A,'维护-日期'!B2,'计算过程-数据汇总'!$L:$L) -> 0 | E9: =SUMIF('计算过程-数据汇总'!$A:$A,'维护-日期'!C2,'计算过程-数据汇总'!$L:$L) -> 0 | F9: =SUMIF('计算过程-数据汇总'!$A:$A,'维护-日期'!D2,'计算过程-数据汇总'!$L:$L) -> 0 | G9: =SUMIF('计算过程-数据汇总'!$A:$A,'维护-日期'!E2,'计算过程-数据汇总'!$L:$L) -> 0 | H9: =SUMIF('计算过程-数据汇总'!$A:$A,'维护-日期'!F2,'计算过程-数据汇总'!$L:$L) -> 0 | I9: =SUMIF('计算过程-数据汇总'!$A:$A,'维护-日期'!G2,'计算过程-数据汇总'!$L:$L) -> 0 | J9: =SUMIF('计算过程-数据汇总'!$A:$A,'维护-日期'!H2,'计算过程-数据汇总'!$L:$L) -> 0 | K9: =SUMIF('计算过程-数据汇总'!$A:$A,'维护-日期'!I2,'计算过程-数据汇总'!$L:$L) -> 0 | ... AH9: =SUMIF('计算过程-数据汇总'!$A:$A,'维护-日期'!AF2,'计算过程-数据汇总'!$L:$L) -> 0
B10: 中长期偏差考核（月考核）
B11: 退补清算
B12: 其他
B13: 零售成本电价（元/MWh） | C13: 372
B14: 预估零售成本电费（元） | C14: =C13*C3 -> 5223119.6
B15: 零售成本电费（元） | C15: =C13*C2 -> 5223119.6
B17: 交易电费（元） | C17: =SUM(D17:AH17) -> 5223119.6 | D17: =D18+D19+D22 -> 170523.31 | E17: =E18+E19+E22 -> 170523.31 | F17: =F18+F19+F22 -> 170523.31 | G17: =G18+G19+G22 -> 170523.31 | H17: =H18+H19+H22 -> 162635.42 | I17: =I18+I19+I22 -> 162635.42 | J17: =J18+J19+J22 -> 170523.31 | K17: =K18+K19+K22 -> 170523.31 | ... AH17: =AH18+AH19+AH22 -> 170523.31
B18: 若全量进日前的电费 | C18: =SUM(D18:AH18) -> 5223119.6 | D18: =SUMIF('计算过程-数据汇总'!$A:$A,'维护-日期'!B2,'计算过程-数据汇总'!$M:$M) -> 170523.31 | E18: =SUMIF('计算过程-数据汇总'!$A:$A,'维护-日期'!C2,'计算过程-数据汇总'!$M:$M) -> 170523.31 | F18: =SUMIF('计算过程-数据汇总'!$A:$A,'维护-日期'!D2,'计算过程-数据汇总'!$M:$M) -> 170523.31 | G18: =SUMIF('计算过程-数据汇总'!$A:$A,'维护-日期'!E2,'计算过程-数据汇总'!$M:$M) -> 170523.31 | H18: =SUMIF('计算过程-数据汇总'!$A:$A,'维护-日期'!F2,'计算过程-数据汇总'!$M:$M) -> 162635.42 | I18: =SUMIF('计算过程-数据汇总'!$A:$A,'维护-日期'!G2,'计算过程-数据汇总'!$M:$M) -> 162635.42 | J18: =SUMIF('计算过程-数据汇总'!$A:$A,'维护-日期'!H2,'计算过程-数据汇总'!$M:$M) -> 170523.31 | K18: =SUMIF('计算过程-数据汇总'!$A:$A,'维护-日期'!I2,'计算过程-数据汇总'!$M:$M) -> 170523.31 | ... AH18: =SUMIF('计算过程-数据汇总'!$A:$A,'维护-日期'!AF2,'计算过程-数据汇总'!$M:$M) -> 170523.31
B19: 日前策略导致电费变动 | C19: =SUM(D19:AH19) -> 0 | D19: =D20+D21 -> 0 | E19: =E20+E21 -> 0 | F19: =F20+F21 -> 0 | G19: =G20+G21 -> 0 | H19: =H20+H21 -> 0 | I19: =I20+I21 -> 0 | J19: =J20+J21 -> 0 | K19: =K20+K21 -> 0 | ... AH19: =AH20+AH21 -> 0
B20: 预测偏差产生电费 | C20: =SUM(D20:AH20) -> 0 | D20: =SUMIF('计算过程-数据汇总'!$A:$A,'维护-日期'!B2,'计算过程-数据汇总'!$N:$N) -> 0 | E20: =SUMIF('计算过程-数据汇总'!$A:$A,'维护-日期'!C2,'计算过程-数据汇总'!$N:$N) -> 0 | F20: =SUMIF('计算过程-数据汇总'!$A:$A,'维护-日期'!D2,'计算过程-数据汇总'!$N:$N) -> 0 | G20: =SUMIF('计算过程-数据汇总'!$A:$A,'维护-日期'!E2,'计算过程-数据汇总'!$N:$N) -> 0 | H20: =SUMIF('计算过程-数据汇总'!$A:$A,'维护-日期'!F2,'计算过程-数据汇总'!$N:$N) -> 0 | I20: =SUMIF('计算过程-数据汇总'!$A:$A,'维护-日期'!G2,'计算过程-数据汇总'!$N:$N) -> 0 | J20: =SUMIF('计算过程-数据汇总'!$A:$A,'维护-日期'!H2,'计算过程-数据汇总'!$N:$N) -> 0 | K20: =SUMIF('计算过程-数据汇总'!$A:$A,'维护-日期'!I2,'计算过程-数据汇总'!$N:$N) -> 0 | ... AH20: =SUMIF('计算过程-数据汇总'!$A:$A,'维护-日期'!AF2,'计算过程-数据汇总'!$N:$N) -> 0
B21: 申报策略影响电费 | C21: =SUM(D21:AH21) -> 0 | D21: =SUMIF('计算过程-数据汇总'!$A:$A,'维护-日期'!B2,'计算过程-数据汇总'!$O:$O) -> 0 | E21: =SUMIF('计算过程-数据汇总'!$A:$A,'维护-日期'!C2,'计算过程-数据汇总'!$O:$O) -> 0 | F21: =SUMIF('计算过程-数据汇总'!$A:$A,'维护-日期'!D2,'计算过程-数据汇总'!$O:$O) -> 0 | G21: =SUMIF('计算过程-数据汇总'!$A:$A,'维护-日期'!E2,'计算过程-数据汇总'!$O:$O) -> 0 | H21: =SUMIF('计算过程-数据汇总'!$A:$A,'维护-日期'!F2,'计算过程-数据汇总'!$O:$O) -> 0 | I21: =SUMIF('计算过程-数据汇总'!$A:$A,'维护-日期'!G2,'计算过程-数据汇总'!$O:$O) -> 0 | J21: =SUMIF('计算过程-数据汇总'!$A:$A,'维护-日期'!H2,'计算过程-数据汇总'!$O:$O) -> 0 | K21: =SUMIF('计算过程-数据汇总'!$A:$A,'维护-日期'!I2,'计算过程-数据汇总'!$O:$O) -> 0 | ... AH21: =SUMIF('计算过程-数据汇总'!$A:$A,'维护-日期'!AF2,'计算过程-数据汇总'!$O:$O) -> 0
B22: 中长期策略导致电费变动 | C22: =SUM(D22:AH22) -> 0 | D22: =SUM(D23:D37) -> 0 | E22: =SUM(E23:E37) -> 0 | F22: =SUM(F23:F37) -> 0 | G22: =SUM(G23:G37) -> 0 | H22: =SUM(H23:H37) -> 0 | I22: =SUM(I23:I37) -> 0 | J22: =SUM(J23:J37) -> 0 | K22: =SUM(K23:K37) -> 0 | ... AH22: =SUM(AH23:AH37) -> 0
B23: ='计算过程-数据汇总'!AA1 -> 年度双边策略电费变动（元） | C23: =SUM(D23:AH23) -> 0 | D23: =SUMIF('计算过程-数据汇总'!$A:$A,'维护-日期'!B2,'计算过程-数据汇总'!$AA:$AA) -> 0 | E23: =SUMIF('计算过程-数据汇总'!$A:$A,'维护-日期'!C2,'计算过程-数据汇总'!$AA:$AA) -> 0 | F23: =SUMIF('计算过程-数据汇总'!$A:$A,'维护-日期'!D2,'计算过程-数据汇总'!$AA:$AA) -> 0 | G23: =SUMIF('计算过程-数据汇总'!$A:$A,'维护-日期'!E2,'计算过程-数据汇总'!$AA:$AA) -> 0 | H23: =SUMIF('计算过程-数据汇总'!$A:$A,'维护-日期'!F2,'计算过程-数据汇总'!$AA:$AA) -> 0 | I23: =SUMIF('计算过程-数据汇总'!$A:$A,'维护-日期'!G2,'计算过程-数据汇总'!$AA:$AA) -> 0 | J23: =SUMIF('计算过程-数据汇总'!$A:$A,'维护-日期'!H2,'计算过程-数据汇总'!$AA:$AA) -> 0 | K23: =SUMIF('计算过程-数据汇总'!$A:$A,'维护-日期'!I2,'计算过程-数据汇总'!$AA:$AA) -> 0 | ... AH23: =SUMIF('计算过程-数据汇总'!$A:$A,'维护-日期'!AF2,'计算过程-数据汇总'!$AA:$AA) -> 0
B24: ='计算过程-数据汇总'!AD1 -> 年度挂牌策略电费变动（元） | C24: =SUM(D24:AH24) -> 0 | D24: =SUMIF('计算过程-数据汇总'!$A:$A,'维护-日期'!B2,'计算过程-数据汇总'!$AD:$AD) -> 0 | E24: =SUMIF('计算过程-数据汇总'!$A:$A,'维护-日期'!C2,'计算过程-数据汇总'!$AD:$AD) -> 0 | F24: =SUMIF('计算过程-数据汇总'!$A:$A,'维护-日期'!D2,'计算过程-数据汇总'!$AD:$AD) -> 0 | G24: =SUMIF('计算过程-数据汇总'!$A:$A,'维护-日期'!E2,'计算过程-数据汇总'!$AD:$AD) -> 0 | H24: =SUMIF('计算过程-数据汇总'!$A:$A,'维护-日期'!F2,'计算过程-数据汇总'!$AD:$AD) -> 0 | I24: =SUMIF('计算过程-数据汇总'!$A:$A,'维护-日期'!G2,'计算过程-数据汇总'!$AD:$AD) -> 0 | J24: =SUMIF('计算过程-数据汇总'!$A:$A,'维护-日期'!H2,'计算过程-数据汇总'!$AD:$AD) -> 0 | K24: =SUMIF('计算过程-数据汇总'!$A:$A,'维护-日期'!I2,'计算过程-数据汇总'!$AD:$AD) -> 0 | ... AH24: =SUMIF('计算过程-数据汇总'!$A:$A,'维护-日期'!AF2,'计算过程-数据汇总'!$AD:$AD) -> 0
B25: ='计算过程-数据汇总'!AG1 -> 年度集中竞争策略电费变动（元） | C25: =SUM(D25:AH25) -> 0 | D25: =SUMIF('计算过程-数据汇总'!$A:$A,'维护-日期'!B2,'计算过程-数据汇总'!$AG:$AG) -> 0 | E25: =SUMIF('计算过程-数据汇总'!$A:$A,'维护-日期'!C2,'计算过程-数据汇总'!$AG:$AG) -> 0 | F25: =SUMIF('计算过程-数据汇总'!$A:$A,'维护-日期'!D2,'计算过程-数据汇总'!$AG:$AG) -> 0 | G25: =SUMIF('计算过程-数据汇总'!$A:$A,'维护-日期'!E2,'计算过程-数据汇总'!$AG:$AG) -> 0 | H25: =SUMIF('计算过程-数据汇总'!$A:$A,'维护-日期'!F2,'计算过程-数据汇总'!$AG:$AG) -> 0 | I25: =SUMIF('计算过程-数据汇总'!$A:$A,'维护-日期'!G2,'计算过程-数据汇总'!$AG:$AG) -> 0 | J25: =SUMIF('计算过程-数据汇总'!$A:$A,'维护-日期'!H2,'计算过程-数据汇总'!$AG:$AG) -> 0 | K25: =SUMIF('计算过程-数据汇总'!$A:$A,'维护-日期'!I2,'计算过程-数据汇总'!$AG:$AG) -> 0 | ... AH25: =SUMIF('计算过程-数据汇总'!$A:$A,'维护-日期'!AF2,'计算过程-数据汇总'!$AG:$AG) -> 0
B26: ='计算过程-数据汇总'!AJ1 -> 年度绿电双边策略电费变动（元） | C26: =SUM(D26:AH26) -> 0 | D26: =SUMIF('计算过程-数据汇总'!$A:$A,'维护-日期'!B2,'计算过程-数据汇总'!$AJ:$AJ) -> 0 | E26: =SUMIF('计算过程-数据汇总'!$A:$A,'维护-日期'!C2,'计算过程-数据汇总'!$AJ:$AJ) -> 0 | F26: =SUMIF('计算过程-数据汇总'!$A:$A,'维护-日期'!D2,'计算过程-数据汇总'!$AJ:$AJ) -> 0 | G26: =SUMIF('计算过程-数据汇总'!$A:$A,'维护-日期'!E2,'计算过程-数据汇总'!$AJ:$AJ) -> 0 | H26: =SUMIF('计算过程-数据汇总'!$A:$A,'维护-日期'!F2,'计算过程-数据汇总'!$AJ:$AJ) -> 0 | I26: =SUMIF('计算过程-数据汇总'!$A:$A,'维护-日期'!G2,'计算过程-数据汇总'!$AJ:$AJ) -> 0 | J26: =SUMIF('计算过程-数据汇总'!$A:$A,'维护-日期'!H2,'计算过程-数据汇总'!$AJ:$AJ) -> 0 | K26: =SUMIF('计算过程-数据汇总'!$A:$A,'维护-日期'!I2,'计算过程-数据汇总'!$AJ:$AJ) -> 0 | ... AH26: =SUMIF('计算过程-数据汇总'!$A:$A,'维护-日期'!AF2,'计算过程-数据汇总'!$AJ:$AJ) -> 0
B27: ='计算过程-数据汇总'!AM1 -> 多月连续集中策略电费变动（元） | C27: =SUM(D27:AH27) -> 0 | D27: =SUMIF('计算过程-数据汇总'!$A:$A,'维护-日期'!B2,'计算过程-数据汇总'!$AM:$AM) -> 0 | E27: =SUMIF('计算过程-数据汇总'!$A:$A,'维护-日期'!C2,'计算过程-数据汇总'!$AM:$AM) -> 0 | F27: =SUMIF('计算过程-数据汇总'!$A:$A,'维护-日期'!D2,'计算过程-数据汇总'!$AM:$AM) -> 0 | G27: =SUMIF('计算过程-数据汇总'!$A:$A,'维护-日期'!E2,'计算过程-数据汇总'!$AM:$AM) -> 0 | H27: =SUMIF('计算过程-数据汇总'!$A:$A,'维护-日期'!F2,'计算过程-数据汇总'!$AM:$AM) -> 0 | I27: =SUMIF('计算过程-数据汇总'!$A:$A,'维护-日期'!G2,'计算过程-数据汇总'!$AM:$AM) -> 0 | J27: =SUMIF('计算过程-数据汇总'!$A:$A,'维护-日期'!H2,'计算过程-数据汇总'!$AM:$AM) -> 0 | K27: =SUMIF('计算过程-数据汇总'!$A:$A,'维护-日期'!I2,'计算过程-数据汇总'!$AM:$AM) -> 0 | ... AH27: =SUMIF('计算过程-数据汇总'!$A:$A,'维护-日期'!AF2,'计算过程-数据汇总'!$AM:$AM) -> 0
B28: ='计算过程-数据汇总'!AP1 -> 月度跨省外送策略电费变动（元） | C28: =SUM(D28:AH28) -> 0 | D28: =SUMIF('计算过程-数据汇总'!$A:$A,'维护-日期'!B2,'计算过程-数据汇总'!$AP:$AP) -> 0 | E28: =SUMIF('计算过程-数据汇总'!$A:$A,'维护-日期'!C2,'计算过程-数据汇总'!$AP:$AP) -> 0 | F28: =SUMIF('计算过程-数据汇总'!$A:$A,'维护-日期'!D2,'计算过程-数据汇总'!$AP:$AP) -> 0 | G28: =SUMIF('计算过程-数据汇总'!$A:$A,'维护-日期'!E2,'计算过程-数据汇总'!$AP:$AP) -> 0 | H28: =SUMIF('计算过程-数据汇总'!$A:$A,'维护-日期'!F2,'计算过程-数据汇总'!$AP:$AP) -> 0 | I28: =SUMIF('计算过程-数据汇总'!$A:$A,'维护-日期'!G2,'计算过程-数据汇总'!$AP:$AP) -> 0 | J28: =SUMIF('计算过程-数据汇总'!$A:$A,'维护-日期'!H2,'计算过程-数据汇总'!$AP:$AP) -> 0 | K28: =SUMIF('计算过程-数据汇总'!$A:$A,'维护-日期'!I2,'计算过程-数据汇总'!$AP:$AP) -> 0 | ... AH28: =SUMIF('计算过程-数据汇总'!$A:$A,'维护-日期'!AF2,'计算过程-数据汇总'!$AP:$AP) -> 0
B29: ='计算过程-数据汇总'!AS1 -> 月度双边策略电费变动（元） | C29: =SUM(D29:AH29) -> 0 | D29: =SUMIF('计算过程-数据汇总'!$A:$A,'维护-日期'!B2,'计算过程-数据汇总'!$AS:$AS) -> 0 | E29: =SUMIF('计算过程-数据汇总'!$A:$A,'维护-日期'!C2,'计算过程-数据汇总'!$AS:$AS) -> 0 | F29: =SUMIF('计算过程-数据汇总'!$A:$A,'维护-日期'!D2,'计算过程-数据汇总'!$AS:$AS) -> 0 | G29: =SUMIF('计算过程-数据汇总'!$A:$A,'维护-日期'!E2,'计算过程-数据汇总'!$AS:$AS) -> 0 | H29: =SUMIF('计算过程-数据汇总'!$A:$A,'维护-日期'!F2,'计算过程-数据汇总'!$AS:$AS) -> 0 | I29: =SUMIF('计算过程-数据汇总'!$A:$A,'维护-日期'!G2,'计算过程-数据汇总'!$AS:$AS) -> 0 | J29: =SUMIF('计算过程-数据汇总'!$A:$A,'维护-日期'!H2,'计算过程-数据汇总'!$AS:$AS) -> 0 | K29: =SUMIF('计算过程-数据汇总'!$A:$A,'维护-日期'!I2,'计算过程-数据汇总'!$AS:$AS) -> 0 | ... AH29: =SUMIF('计算过程-数据汇总'!$A:$A,'维护-日期'!AF2,'计算过程-数据汇总'!$AS:$AS) -> 0
B30: ='计算过程-数据汇总'!AV1 -> 月度绿电挂牌策略电费变动（元） | C30: =SUM(D30:AH30) -> 0 | D30: =SUMIF('计算过程-数据汇总'!$A:$A,'维护-日期'!B2,'计算过程-数据汇总'!$AV:$AV) -> 0 | E30: =SUMIF('计算过程-数据汇总'!$A:$A,'维护-日期'!C2,'计算过程-数据汇总'!$AV:$AV) -> 0 | F30: =SUMIF('计算过程-数据汇总'!$A:$A,'维护-日期'!D2,'计算过程-数据汇总'!$AV:$AV) -> 0 | G30: =SUMIF('计算过程-数据汇总'!$A:$A,'维护-日期'!E2,'计算过程-数据汇总'!$AV:$AV) -> 0 | H30: =SUMIF('计算过程-数据汇总'!$A:$A,'维护-日期'!F2,'计算过程-数据汇总'!$AV:$AV) -> 0 | I30: =SUMIF('计算过程-数据汇总'!$A:$A,'维护-日期'!G2,'计算过程-数据汇总'!$AV:$AV) -> 0 | J30: =SUMIF('计算过程-数据汇总'!$A:$A,'维护-日期'!H2,'计算过程-数据汇总'!$AV:$AV) -> 0 | K30: =SUMIF('计算过程-数据汇总'!$A:$A,'维护-日期'!I2,'计算过程-数据汇总'!$AV:$AV) -> 0 | ... AH30: =SUMIF('计算过程-数据汇总'!$A:$A,'维护-日期'!AF2,'计算过程-数据汇总'!$AV:$AV) -> 0
B31: ='计算过程-数据汇总'!AY1 -> 月度绿电集中策略电费变动（元） | C31: =SUM(D31:AH31) -> 0 | D31: =SUMIF('计算过程-数据汇总'!$A:$A,'维护-日期'!B2,'计算过程-数据汇总'!$AY:$AY) -> 0 | E31: =SUMIF('计算过程-数据汇总'!$A:$A,'维护-日期'!C2,'计算过程-数据汇总'!$AY:$AY) -> 0 | F31: =SUMIF('计算过程-数据汇总'!$A:$A,'维护-日期'!D2,'计算过程-数据汇总'!$AY:$AY) -> 0 | G31: =SUMIF('计算过程-数据汇总'!$A:$A,'维护-日期'!E2,'计算过程-数据汇总'!$AY:$AY) -> 0 | H31: =SUMIF('计算过程-数据汇总'!$A:$A,'维护-日期'!F2,'计算过程-数据汇总'!$AY:$AY) -> 0 | I31: =SUMIF('计算过程-数据汇总'!$A:$A,'维护-日期'!G2,'计算过程-数据汇总'!$AY:$AY) -> 0 | J31: =SUMIF('计算过程-数据汇总'!$A:$A,'维护-日期'!H2,'计算过程-数据汇总'!$AY:$AY) -> 0 | K31: =SUMIF('计算过程-数据汇总'!$A:$A,'维护-日期'!I2,'计算过程-数据汇总'!$AY:$AY) -> 0 | ... AH31: =SUMIF('计算过程-数据汇总'!$A:$A,'维护-日期'!AF2,'计算过程-数据汇总'!$AY:$AY) -> 0
B32: ='计算过程-数据汇总'!BB1 -> 月度集中（市场用户负荷曲线）策略电费变动（元） | C32: =SUM(D32:AH32) -> 0 | D32: =SUMIF('计算过程-数据汇总'!$A:$A,'维护-日期'!B2,'计算过程-数据汇总'!$BB:$BB) -> 0 | E32: =SUMIF('计算过程-数据汇总'!$A:$A,'维护-日期'!C2,'计算过程-数据汇总'!$BB:$BB) -> 0 | F32: =SUMIF('计算过程-数据汇总'!$A:$A,'维护-日期'!D2,'计算过程-数据汇总'!$BB:$BB) -> 0 | G32: =SUMIF('计算过程-数据汇总'!$A:$A,'维护-日期'!E2,'计算过程-数据汇总'!$BB:$BB) -> 0 | H32: =SUMIF('计算过程-数据汇总'!$A:$A,'维护-日期'!F2,'计算过程-数据汇总'!$BB:$BB) -> 0 | I32: =SUMIF('计算过程-数据汇总'!$A:$A,'维护-日期'!G2,'计算过程-数据汇总'!$BB:$BB) -> 0 | J32: =SUMIF('计算过程-数据汇总'!$A:$A,'维护-日期'!H2,'计算过程-数据汇总'!$BB:$BB) -> 0 | K32: =SUMIF('计算过程-数据汇总'!$A:$A,'维护-日期'!I2,'计算过程-数据汇总'!$BB:$BB) -> 0 | ... AH32: =SUMIF('计算过程-数据汇总'!$A:$A,'维护-日期'!AF2,'计算过程-数据汇总'!$BB:$BB) -> 0
B33: ='计算过程-数据汇总'!BE1 -> 月度分时集中策略电费变动（元） | C33: =SUM(D33:AH33) -> 0 | D33: =SUMIF('计算过程-数据汇总'!$A:$A,'维护-日期'!B2,'计算过程-数据汇总'!$BE:$BE) -> 0 | E33: =SUMIF('计算过程-数据汇总'!$A:$A,'维护-日期'!C2,'计算过程-数据汇总'!$BE:$BE) -> 0 | F33: =SUMIF('计算过程-数据汇总'!$A:$A,'维护-日期'!D2,'计算过程-数据汇总'!$BE:$BE) -> 0 | G33: =SUMIF('计算过程-数据汇总'!$A:$A,'维护-日期'!E2,'计算过程-数据汇总'!$BE:$BE) -> 0 | H33: =SUMIF('计算过程-数据汇总'!$A:$A,'维护-日期'!F2,'计算过程-数据汇总'!$BE:$BE) -> 0 | I33: =SUMIF('计算过程-数据汇总'!$A:$A,'维护-日期'!G2,'计算过程-数据汇总'!$BE:$BE) -> 0 | J33: =SUMIF('计算过程-数据汇总'!$A:$A,'维护-日期'!H2,'计算过程-数据汇总'!$BE:$BE) -> 0 | K33: =SUMIF('计算过程-数据汇总'!$A:$A,'维护-日期'!I2,'计算过程-数据汇总'!$BE:$BE) -> 0 | ... AH33: =SUMIF('计算过程-数据汇总'!$A:$A,'维护-日期'!AF2,'计算过程-数据汇总'!$BE:$BE) -> 0
B34: ='计算过程-数据汇总'!BH1 -> 月内第一次多日策略电费变动（元） | C34: =SUM(D34:AH34) -> 0 | D34: =SUMIF('计算过程-数据汇总'!$A:$A,'维护-日期'!B2,'计算过程-数据汇总'!$BH:$BH) -> 0 | E34: =SUMIF('计算过程-数据汇总'!$A:$A,'维护-日期'!C2,'计算过程-数据汇总'!$BH:$BH) -> 0 | F34: =SUMIF('计算过程-数据汇总'!$A:$A,'维护-日期'!D2,'计算过程-数据汇总'!$BH:$BH) -> 0 | G34: =SUMIF('计算过程-数据汇总'!$A:$A,'维护-日期'!E2,'计算过程-数据汇总'!$BH:$BH) -> 0 | H34: =SUMIF('计算过程-数据汇总'!$A:$A,'维护-日期'!F2,'计算过程-数据汇总'!$BH:$BH) -> 0 | I34: =SUMIF('计算过程-数据汇总'!$A:$A,'维护-日期'!G2,'计算过程-数据汇总'!$BH:$BH) -> 0 | J34: =SUMIF('计算过程-数据汇总'!$A:$A,'维护-日期'!H2,'计算过程-数据汇总'!$BH:$BH) -> 0 | K34: =SUMIF('计算过程-数据汇总'!$A:$A,'维护-日期'!I2,'计算过程-数据汇总'!$BH:$BH) -> 0 | ... AH34: =SUMIF('计算过程-数据汇总'!$A:$A,'维护-日期'!AF2,'计算过程-数据汇总'!$BH:$BH) -> 0
B35: ='计算过程-数据汇总'!BK1 -> 月内第二次多日策略电费变动（元） | C35: =SUM(D35:AH35) -> 0 | D35: =SUMIF('计算过程-数据汇总'!$A:$A,'维护-日期'!B2,'计算过程-数据汇总'!$BK:$BK) -> 0 | E35: =SUMIF('计算过程-数据汇总'!$A:$A,'维护-日期'!C2,'计算过程-数据汇总'!$BK:$BK) -> 0 | F35: =SUMIF('计算过程-数据汇总'!$A:$A,'维护-日期'!D2,'计算过程-数据汇总'!$BK:$BK) -> 0 | G35: =SUMIF('计算过程-数据汇总'!$A:$A,'维护-日期'!E2,'计算过程-数据汇总'!$BK:$BK) -> 0 | H35: =SUMIF('计算过程-数据汇总'!$A:$A,'维护-日期'!F2,'计算过程-数据汇总'!$BK:$BK) -> 0 | I35: =SUMIF('计算过程-数据汇总'!$A:$A,'维护-日期'!G2,'计算过程-数据汇总'!$BK:$BK) -> 0 | J35: =SUMIF('计算过程-数据汇总'!$A:$A,'维护-日期'!H2,'计算过程-数据汇总'!$BK:$BK) -> 0 | K35: =SUMIF('计算过程-数据汇总'!$A:$A,'维护-日期'!I2,'计算过程-数据汇总'!$BK:$BK) -> 0 | ... AH35: =SUMIF('计算过程-数据汇总'!$A:$A,'维护-日期'!AF2,'计算过程-数据汇总'!$BK:$BK) -> 0
B36: ='计算过程-数据汇总'!BN1 -> 月内合同转让策略电费变动（元） | C36: =SUM(D36:AH36) -> 0 | D36: =SUMIF('计算过程-数据汇总'!$A:$A,'维护-日期'!B2,'计算过程-数据汇总'!$BN:$BN) -> 0 | E36: =SUMIF('计算过程-数据汇总'!$A:$A,'维护-日期'!C2,'计算过程-数据汇总'!$BN:$BN) -> 0 | F36: =SUMIF('计算过程-数据汇总'!$A:$A,'维护-日期'!D2,'计算过程-数据汇总'!$BN:$BN) -> 0 | G36: =SUMIF('计算过程-数据汇总'!$A:$A,'维护-日期'!E2,'计算过程-数据汇总'!$BN:$BN) -> 0 | H36: =SUMIF('计算过程-数据汇总'!$A:$A,'维护-日期'!F2,'计算过程-数据汇总'!$BN:$BN) -> 0 | I36: =SUMIF('计算过程-数据汇总'!$A:$A,'维护-日期'!G2,'计算过程-数据汇总'!$BN:$BN) -> 0 | J36: =SUMIF('计算过程-数据汇总'!$A:$A,'维护-日期'!H2,'计算过程-数据汇总'!$BN:$BN) -> 0 | K36: =SUMIF('计算过程-数据汇总'!$A:$A,'维护-日期'!I2,'计算过程-数据汇总'!$BN:$BN) -> 0 | ... AH36: =SUMIF('计算过程-数据汇总'!$A:$A,'维护-日期'!AF2,'计算过程-数据汇总'!$BN:$BN) -> 0
B37: ='计算过程-数据汇总'!BQ1 -> 月内周双边策略电费变动（元） | C37: =SUM(D37:AH37) -> 0 | D37: =SUMIF('计算过程-数据汇总'!$A:$A,'维护-日期'!B2,'计算过程-数据汇总'!$BQ:$BQ) -> 0 | E37: =SUMIF('计算过程-数据汇总'!$A:$A,'维护-日期'!C2,'计算过程-数据汇总'!$BQ:$BQ) -> 0 | F37: =SUMIF('计算过程-数据汇总'!$A:$A,'维护-日期'!D2,'计算过程-数据汇总'!$BQ:$BQ) -> 0 | G37: =SUMIF('计算过程-数据汇总'!$A:$A,'维护-日期'!E2,'计算过程-数据汇总'!$BQ:$BQ) -> 0 | H37: =SUMIF('计算过程-数据汇总'!$A:$A,'维护-日期'!F2,'计算过程-数据汇总'!$BQ:$BQ) -> 0 | I37: =SUMIF('计算过程-数据汇总'!$A:$A,'维护-日期'!G2,'计算过程-数据汇总'!$BQ:$BQ) -> 0 | J37: =SUMIF('计算过程-数据汇总'!$A:$A,'维护-日期'!H2,'计算过程-数据汇总'!$BQ:$BQ) -> 0 | K37: =SUMIF('计算过程-数据汇总'!$A:$A,'维护-日期'!I2,'计算过程-数据汇总'!$BQ:$BQ) -> 0 | ... AH37: =SUMIF('计算过程-数据汇总'!$A:$A,'维护-日期'!AF2,'计算过程-数据汇总'!$BQ:$BQ) -> 0
B38: 若全量进中长期的电费 | C38: =SUM(D38:AH38) -> 5223119.6 | D38: =SUMIF('计算过程-数据汇总'!$A:$A,'维护-日期'!B2,'计算过程-数据汇总'!$R:$R) -> 170523.31 | E38: =SUMIF('计算过程-数据汇总'!$A:$A,'维护-日期'!C2,'计算过程-数据汇总'!$R:$R) -> 170523.31 | F38: =SUMIF('计算过程-数据汇总'!$A:$A,'维护-日期'!D2,'计算过程-数据汇总'!$R:$R) -> 170523.31 | G38: =SUMIF('计算过程-数据汇总'!$A:$A,'维护-日期'!E2,'计算过程-数据汇总'!$R:$R) -> 170523.31 | H38: =SUMIF('计算过程-数据汇总'!$A:$A,'维护-日期'!F2,'计算过程-数据汇总'!$R:$R) -> 162635.42 | I38: =SUMIF('计算过程-数据汇总'!$A:$A,'维护-日期'!G2,'计算过程-数据汇总'!$R:$R) -> 162635.42 | J38: =SUMIF('计算过程-数据汇总'!$A:$A,'维护-日期'!H2,'计算过程-数据汇总'!$R:$R) -> 170523.31 | K38: =SUMIF('计算过程-数据汇总'!$A:$A,'维护-日期'!I2,'计算过程-数据汇总'!$R:$R) -> 170523.31 | ... AH38: =SUMIF('计算过程-数据汇总'!$A:$A,'维护-日期'!AF2,'计算过程-数据汇总'!$R:$R) -> 170523.31
B39: 日前策略导致电费损益 | C39: =SUM(D39:AH39) -> 0 | D39: =D40+D41 -> 0 | E39: =E40+E41 -> 0 | F39: =F40+F41 -> 0 | G39: =G40+G41 -> 0 | H39: =H40+H41 -> 0 | I39: =I40+I41 -> 0 | J39: =J40+J41 -> 0 | K39: =K40+K41 -> 0 | ... AH39: =AH40+AH41 -> 0
B40: 预测偏差产生电费 | C40: =SUM(D40:AH40) -> 0 | D40: =SUMIF('计算过程-数据汇总'!$A:$A,'维护-日期'!B2,'计算过程-数据汇总'!$U:$U) -> 0 | E40: =SUMIF('计算过程-数据汇总'!$A:$A,'维护-日期'!C2,'计算过程-数据汇总'!$U:$U) -> 0 | F40: =SUMIF('计算过程-数据汇总'!$A:$A,'维护-日期'!D2,'计算过程-数据汇总'!$U:$U) -> 0 | G40: =SUMIF('计算过程-数据汇总'!$A:$A,'维护-日期'!E2,'计算过程-数据汇总'!$U:$U) -> 0 | H40: =SUMIF('计算过程-数据汇总'!$A:$A,'维护-日期'!F2,'计算过程-数据汇总'!$U:$U) -> 0 | I40: =SUMIF('计算过程-数据汇总'!$A:$A,'维护-日期'!G2,'计算过程-数据汇总'!$U:$U) -> 0 | J40: =SUMIF('计算过程-数据汇总'!$A:$A,'维护-日期'!H2,'计算过程-数据汇总'!$U:$U) -> 0 | K40: =SUMIF('计算过程-数据汇总'!$A:$A,'维护-日期'!I2,'计算过程-数据汇总'!$U:$U) -> 0 | ... AH40: =SUMIF('计算过程-数据汇总'!$A:$A,'维护-日期'!AF2,'计算过程-数据汇总'!$U:$U) -> 0
B41: 申报策略影响电费 | C41: =SUM(D41:AH41) -> 0 | D41: =SUMIF('计算过程-数据汇总'!$A:$A,'维护-日期'!B2,'计算过程-数据汇总'!$V:$V) -> 0 | E41: =SUMIF('计算过程-数据汇总'!$A:$A,'维护-日期'!C2,'计算过程-数据汇总'!$V:$V) -> 0 | F41: =SUMIF('计算过程-数据汇总'!$A:$A,'维护-日期'!D2,'计算过程-数据汇总'!$V:$V) -> 0 | G41: =SUMIF('计算过程-数据汇总'!$A:$A,'维护-日期'!E2,'计算过程-数据汇总'!$V:$V) -> 0 | H41: =SUMIF('计算过程-数据汇总'!$A:$A,'维护-日期'!F2,'计算过程-数据汇总'!$V:$V) -> 0 | I41: =SUMIF('计算过程-数据汇总'!$A:$A,'维护-日期'!G2,'计算过程-数据汇总'!$V:$V) -> 0 | J41: =SUMIF('计算过程-数据汇总'!$A:$A,'维护-日期'!H2,'计算过程-数据汇总'!$V:$V) -> 0 | K41: =SUMIF('计算过程-数据汇总'!$A:$A,'维护-日期'!I2,'计算过程-数据汇总'!$V:$V) -> 0 | ... AH41: =SUMIF('计算过程-数据汇总'!$A:$A,'维护-日期'!AF2,'计算过程-数据汇总'!$V:$V) -> 0
...

Sheet 维护-日期
A2: 复盘日期 | B2: {=TRANSPOSE(A3:A33)} -> 46266 | C2: 46267 | D2: 46268 | E2: 46269 | F2: 46270 | G2: 46271 | H2: 46272 | I2: 46273 | J2: 46274 | K2: 46275 | L2: 46276 | M2: 46277 | N2: 46278 | O2: 46279 | P2: 46280 | Q2: 46281 | R2: 46282 | S2: 46283 | T2: 46284 | U2: 46285 | V2: 46286 | W2: 46287 | X2: 46288 | Y2: 46289 | Z2: 46290 | AA2: 46291 | AB2: 46292 | AC2: 46293 | AD2: 46294 | AE2: 46295 | AF2: 0
A3: 46266
A4: 46267
A5: 46268
A6: 46269
A7: 46270
A8: 46271
A9: 46272
A10: 46273
A11: 46274
A12: 46275
A13: 46276
A14: 46277
... A32: 46295

Sheet 计算过程-数据汇总
A1: 日期 | B1: 时间 | C1: 实际用电量 | D1: =持仓数据!B1 -> 预估用电量 | E1: 日前申报电量 | F1: =持仓数据!B70 -> 中长期合约电量(MWh) | G1: 日前统一结算点价格 | H1: 实时统一结算点价格 | I1: 省间现货电量 | J1: 省间现货电价 | K1: =持仓数据!B103 -> 中长期合约加权电价(元/MWh) | L1: 省间电费 | M1: 全量日前电费 | N1: 日前预测偏差产生电费 | O1: 日前申报策略影响电费 | P1: 中长期申报策略影响电费 | Q1: 日前偏差超额回收（日考核） | R1: 全电量中长期电费 | S1: 中长期预测偏差产生电费（全量中长期） | T1: 中长期申报策略影响电费（全量中长期） | U1: 日前预测偏差产生电费（全量中长期） | V1: 日前申报策略影响电费（全量中长期） | X1: 分时剩余限额 | Y1: =交易记录!C3 -> 年度双边交易电量(MWh) | Z1: =交易记录!C34 -> 年度双边交易电价(元/MWh) | AA1: =LEFT(Z1,FIND("交易",Z1)-1)&"策略电费变动（元）" -> 年度双边策略电费变动（元） | AB1: =交易记录!C67 -> 年度挂牌交易电量(MWh) | AC1: =交易记录!C98 -> 年度挂牌交易电价(元/MWh) | AD1: =LEFT(AC1,FIND("交易",AC1)-1)&"策略电费变动（元）" -> 年度挂牌策略电费变动（元） | AE1: =交易记录!C131 -> 年度集中竞争交易电量(MWh) | AF1: =交易记录!C162 -> 年度集中竞争交易电价(元/MWh) | AG1: =LEFT(AF1,FIND("交易",AF1)-1)&"策略电费变动（元）" -> 年度集中竞争策略电费变动（元） | AH1: =交易记录!C195 -> 年度绿电双边交易电量(MWh) | AI1: =交易记录!C226 -> 年度绿电双边交易电价(元/MWh) | AJ1: =LEFT(AI1,FIND("交易",AI1)-1)&"策略电费变动（元）" -> 年度绿电双边策略电费变动（元） | AK1: =交易记录!C259 -> 多月连续集中交易电量(MWh) | AL1: =交易记录!C290 -> 多月连续集中交易电价(元/MWh) | AM1: =LEFT(AL1,FIND("交易",AL1)-1)&"策略电费变动（元）" -> 多月连续集中策略电费变动（元） | AN1: =交易记录!C323 -> 月度跨省外送交易电量(MWh) | AO1: =交易记录!C354 -> 月度跨省外送交易电价(元/MWh) | AP1: =LEFT(AO1,FIND("交易",AO1)-1)&"策略电费变动（元）" -> 月度跨省外送策略电费变动（元） | AQ1: =交易记录!C387 -> 月度双边交易电量(MWh) | AR1: =交易记录!C418 -> 月度双边交易电价(元/MWh) | AS1: =LEFT(AR1,FIND("交易",AR1)-1)&"策略电费变动（元）" -> 月度双边策略电费变动（元） | AT1: =交易记录!C451 -> 月度绿电挂牌交易电量(MWh) | AU1: =交易记录!C482 -> 月度绿电挂牌交易电价(元/MWh) | AV1: =LEFT(AU1,FIND("交易",AU1)-1)&"策略电费变动（元）" -> 月度绿电挂牌策略电费变动（元） | AW1: =交易记录!C515 -> 月度绿电集中交易电量(MWh) | AX1: =交易记录!C546 -> 月度绿电集中交易电价(元/MWh) | AY1: =LEFT(AX1,FIND("交易",AX1)-1)&"策略电费变动（元）" -> 月度绿电集中策略电费变动（元） | AZ1: =交易记录!C579 -> 月度集中（市场用户负荷曲线）交易电量(MWh) | BA1: =交易记录!C610 -> 月度集中（市场用户负荷曲线）交易电价(元/MWh) | BB1: =LEFT(BA1,FIND("交易",BA1)-1)&"策略电费变动（元）" -> 月度集中（市场用户负荷曲线）策略电费变动（元） | BC1: =交易记录!C643 -> 月度分时集中交易电量(MWh) | BD1: =交易记录!C674 -> 月度分时集中交易电价(元/MWh) | BE1: =LEFT(BD1,FIND("交易",BD1)-1)&"策略电费变动（元）" -> 月度分时集中策略电费变动（元） | BF1: =交易记录!C707 -> 月内第一次多日交易电量(MWh) | BG1: =交易记录!C738 -> 月内第一次多日交易电价(元/MWh) | BH1: =LEFT(BG1,FIND("交易",BG1)-1)&"策略电费变动（元）" -> 月内第一次多日策略电费变动（元） | BI1: =交易记录!C771 -> 月内第二次多日交易电量(MWh) | BJ1: =交易记录!C802 -> 月内第二次多日交易电价(元/MWh) | BK1: =LEFT(BJ1,FIND("交易",BJ1)-1)&"策略电费变动（元）" -> 月内第二次多日策略电费变动（元） | BL1: =交易记录!C835 -> 月内合同转让交易电量(MWh) | BM1: =交易记录!C866 -> 月内合同转让交易电价(元/MWh) | BN1: =LEFT(BM1,FIND("交易",BM1)-1)&"策略电费变动（元）" -> 月内合同转让策略电费变动（元） | BO1: =交易记录!C899 -> 月内周双边交易电量(MWh) | BP1: =交易记录!C930 -> 月内周双边交易电价(元/MWh) | BQ1: =LEFT(BP1,FIND("交易",BP1)-1)&"策略电费变动（元）" -> 月内周双边策略电费变动（元）
A2: ='维护-日期'!A$3 -> 46266 | B2: 00:00-01:00 | C2: =D2 -> 16.656 | D2: =ROUND(INDEX(持仓数据!$C$3:$AG$26,MATCH('计算过程-数据汇总'!B2,持仓数据!$B$3:$B$26,0),MATCH('计算过程-数据汇总'!A2,'维护-日期'!$B$2:$AF$2,0)),3) -> 16.656 | E2: =D2*1 -> 16.656 | F2: =持仓数据!C72 -> 0.367 | G2: 372 | H2: 372 | I2: 0 | J2: 0 | K2: =IF(持仓数据!C105="",0,持仓数据!C105) -> 372 | L2: =I2*J2 -> 0 | M2: =IFERROR(C2*G2,0) -> 6196.032 | N2: =IFERROR((D2-C2)*(G2-H2),0) -> 0 | O2: =IFERROR((E2-D2)*(G2-H2),0) -> 0 | P2: =IFERROR(F2*(K2-G2),0) -> 0 | Q2: =IFERROR(IF(ABS((E2-C2)/C2)>0.2,IF(SUM(N2:O2)<0,ABS(G2-H2)*(ABS(C2-E2)-C2*0.2),0),0),IF(SUM(N2:O2)<0,ABS(G2-H2)*(ABS(C2-E2)-C2*0.2),0)) -> 0 | R2: =IFERROR(K2*C2,0) -> 6196.032 | S2: =IFERROR((D2-E2)*(K2-G2),0) -> 0 | T2: =IFERROR((F2-D2)*(K2-G2),0) -> 0 | U2: =IFERROR((D2-C2)*(K2-H2),0) -> 0 | V2: =IFERROR((E2-D2)*(K2-H2),0) -> 0 | X2: =ROUND(D2*1.2-SUM(Y2,AB2,AE2,AH2,AK2,AN2,AQ2,AT2,AW2,AZ2,BC2,BF2,BI2,BL2,BO2),3) -> 19.62 | Y2: =交易记录!D5 -> 0.367 | Z2: =交易记录!D36 -> 372 | AA2: =IFERROR((Z2-G2)*Y2,0) -> 0 | AB2: =交易记录!D69 -> 0 | AC2: =交易记录!D100 -> 0 | AD2: =IFERROR((AC2-$G2)*AB2,0) -> 0 | AE2: =交易记录!D133 -> 0 | AF2: =交易记录!D164 -> 0 | AG2: =IFERROR((AF2-$G2)*AE2,0) -> 0 | AH2: =交易记录!D197 -> 0 | AI2: =交易记录!D228 -> 0 | AJ2: =IFERROR((AI2-$G2)*AH2,0) -> 0 | AK2: =交易记录!D261 -> 0 | AL2: =交易记录!D292 -> 0 | AM2: =IFERROR((AL2-$G2)*AK2,0) -> 0 | AN2: =交易记录!D325 -> 0 | AO2: =交易记录!D356 -> 0 | AP2: =IFERROR((AO2-$G2)*AN2,0) -> 0 | AQ2: =交易记录!D389 -> 0 | AR2: =交易记录!D420 -> 0 | AS2: =IFERROR((AR2-$G2)*AQ2,0) -> 0 | AT2: =交易记录!D453 -> 0 | AU2: =交易记录!D484 -> 0 | AV2: =IFERROR((AU2-$G2)*AT2,0) -> 0 | AW2: =交易记录!D517 -> 0 | AX2: =交易记录!D548 -> 0 | AY2: =IFERROR((AX2-$G2)*AW2,0) -> 0 | AZ2: =交易记录!D581 -> 0 | BA2: =交易记录!D612 -> 0 | BB2: =IFERROR((BA2-$G2)*AZ2,0) -> 0 | BC2: =交易记录!D645 -> 0 | BD2: =交易记录!D676 -> 0 | BE2: =IFERROR((BD2-$G2)*BC2,0) -> 0 | BF2: =交易记录!D709 -> 0 | BG2: =交易记录!D740 -> 0 | BH2: =IFERROR((BG2-$G2)*BF2,0) -> 0 | BI2: =交易记录!D773 -> 0 | BJ2: =交易记录!D804 -> 0 | BK2: =IFERROR((BJ2-$G2)*BI2,0) -> 0 | BL2: =交易记录!D837 -> 0 | BM2: =交易记录!D868 -> 0 | BN2: =IFERROR((BM2-$G2)*BL2,0) -> 0 | BO2: =交易记录!D901 -> 0 | BP2: =交易记录!D932 -> 0 | BQ2: =IFERROR((BP2-$G2)*BO2,0) -> 0
A3: ='维护-日期'!A$3 -> 46266 | B3: 01:00-02:00 | C3: =D3 -> 15.792 | D3: =ROUND(INDEX(持仓数据!$C$3:$AG$26,MATCH('计算过程-数据汇总'!B3,持仓数据!$B$3:$B$26,0),MATCH('计算过程-数据汇总'!A3,'维护-日期'!$B$2:$AF$2,0)),3) -> 15.792 | E3: =D3*1 -> 15.792 | F3: =持仓数据!C73 -> 0.331 | G3: 372 | H3: 372 | I3: 0 | J3: 0 | K3: =IF(持仓数据!C106="",0,持仓数据!C106) -> 372 | L3: =I3*J3 -> 0 | M3: =IFERROR(C3*G3,0) -> 5874.624 | N3: =IFERROR((D3-C3)*(G3-H3),0) -> 0 | O3: =IFERROR((E3-D3)*(G3-H3),0) -> 0 | P3: =IFERROR(F3*(K3-G3),0) -> 0 | Q3: =IFERROR(IF(ABS((E3-C3)/C3)>0.2,IF(SUM(N3:O3)<0,ABS(G3-H3)*(ABS(C3-E3)-C3*0.2),0),0),IF(SUM(N3:O3)<0,ABS(G3-H3)*(ABS(C3-E3)-C3*0.2),0)) -> 0 | R3: =IFERROR(K3*C3,0) -> 5874.624 | S3: =IFERROR((D3-E3)*(K3-G3),0) -> 0 | T3: =IFERROR((F3-D3)*(K3-G3),0) -> 0 | U3: =IFERROR((D3-C3)*(K3-H3),0) -> 0 | V3: =IFERROR((E3-D3)*(K3-H3),0) -> 0 | X3: =ROUND(D3*1.2-SUM(Y3,AB3,AE3,AH3,AK3,AN3,AQ3,AT3,AW3,AZ3,BC3,BF3,BI3,BL3,BO3),3) -> 18.619 | Y3: =交易记录!D6 -> 0.331 | Z3: =交易记录!D37 -> 372 | AA3: =IFERROR((Z3-G3)*Y3,0) -> 0 | AB3: =交易记录!D70 -> 0 | AC3: =交易记录!D101 -> 0 | AD3: =IFERROR((AC3-$G3)*AB3,0) -> 0 | AE3: =交易记录!D134 -> 0 | AF3: =交易记录!D165 -> 0 | AG3: =IFERROR((AF3-$G3)*AE3,0) -> 0 | AH3: =交易记录!D198 -> 0 | AI3: =交易记录!D229 -> 0 | AJ3: =IFERROR((AI3-$G3)*AH3,0) -> 0 | AK3: =交易记录!D262 -> 0 | AL3: =交易记录!D293 -> 0 | AM3: =IFERROR((AL3-$G3)*AK3,0) -> 0 | AN3: =交易记录!D326 -> 0 | AO3: =交易记录!D357 -> 0 | AP3: =IFERROR((AO3-$G3)*AN3,0) -> 0 | AQ3: =交易记录!D390 -> 0 | AR3: =交易记录!D421 -> 0 | AS3: =IFERROR((AR3-$G3)*AQ3,0) -> 0 | AT3: =交易记录!D454 -> 0 | AU3: =交易记录!D485 -> 0 | AV3: =IFERROR((AU3-$G3)*AT3,0) -> 0 | AW3: =交易记录!D518 -> 0 | AX3: =交易记录!D549 -> 0 | AY3: =IFERROR((AX3-$G3)*AW3,0) -> 0 | AZ3: =交易记录!D582 -> 0 | BA3: =交易记录!D613 -> 0 | BB3: =IFERROR((BA3-$G3)*AZ3,0) -> 0 | BC3: =交易记录!D646 -> 0 | BD3: =交易记录!D677 -> 0 | BE3: =IFERROR((BD3-$G3)*BC3,0) -> 0 | BF3: =交易记录!D710 -> 0 | BG3: =交易记录!D741 -> 0 | BH3: =IFERROR((BG3-$G3)*BF3,0) -> 0 | BI3: =交易记录!D774 -> 0 | BJ3: =交易记录!D805 -> 0 | BK3: =IFERROR((BJ3-$G3)*BI3,0) -> 0 | BL3: =交易记录!D838 -> 0 | BM3: =交易记录!D869 -> 0 | BN3: =IFERROR((BM3-$G3)*BL3,0) -> 0 | BO3: =交易记录!D902 -> 0 | BP3: =交易记录!D933 -> 0 | BQ3: =IFERROR((BP3-$G3)*BO3,0) -> 0
A4: ='维护-日期'!A$3 -> 46266 | B4: 02:00-03:00 | C4: =D4 -> 14.822 | D4: =ROUND(INDEX(持仓数据!$C$3:$AG$26,MATCH('计算过程-数据汇总'!B4,持仓数据!$B$3:$B$26,0),MATCH('计算过程-数据汇总'!A4,'维护-日期'!$B$2:$AF$2,0)),3) -> 14.822 | E4: =D4*1 -> 14.822 | F4: =持仓数据!C74 -> 0.238 | G4: 372 | H4: 372 | I4: 0 | J4: 0 | K4: =IF(持仓数据!C107="",0,持仓数据!C107) -> 372 | L4: =I4*J4 -> 0 | M4: =IFERROR(C4*G4,0) -> 5513.784 | N4: =IFERROR((D4-C4)*(G4-H4),0) -> 0 | O4: =IFERROR((E4-D4)*(G4-H4),0) -> 0 | P4: =IFERROR(F4*(K4-G4),0) -> 0 | Q4: =IFERROR(IF(ABS((E4-C4)/C4)>0.2,IF(SUM(N4:O4)<0,ABS(G4-H4)*(ABS(C4-E4)-C4*0.2),0),0),IF(SUM(N4:O4)<0,ABS(G4-H4)*(ABS(C4-E4)-C4*0.2),0)) -> 0 | R4: =IFERROR(K4*C4,0) -> 5513.784 | S4: =IFERROR((D4-E4)*(K4-G4),0) -> 0 | T4: =IFERROR((F4-D4)*(K4-G4),0) -> 0 | U4: =IFERROR((D4-C4)*(K4-H4),0) -> 0 | V4: =IFERROR((E4-D4)*(K4-H4),0) -> 0 | X4: =ROUND(D4*1.2-SUM(Y4,AB4,AE4,AH4,AK4,AN4,AQ4,AT4,AW4,AZ4,BC4,BF4,BI4,BL4,BO4),3) -> 17.548 | Y4: =交易记录!D7 -> 0.238 | Z4: =交易记录!D38 -> 372 | AA4: =IFERROR((Z4-G4)*Y4,0) -> 0 | AB4: =交易记录!D71 -> 0 | AC4: =交易记录!D102 -> 0 | AD4: =IFERROR((AC4-$G4)*AB4,0) -> 0 | AE4: =交易记录!D135 -> 0 | AF4: =交易记录!D166 -> 0 | AG4: =IFERROR((AF4-$G4)*AE4,0) -> 0 | AH4: =交易记录!D199 -> 0 | AI4: =交易记录!D230 -> 0 | AJ4: =IFERROR((AI4-$G4)*AH4,0) -> 0 | AK4: =交易记录!D263 -> 0 | AL4: =交易记录!D294 -> 0 | AM4: =IFERROR((AL4-$G4)*AK4,0) -> 0 | AN4: =交易记录!D327 -> 0 | AO4: =交易记录!D358 -> 0 | AP4: =IFERROR((AO4-$G4)*AN4,0) -> 0 | AQ4: =交易记录!D391 -> 0 | AR4: =交易记录!D422 -> 0 | AS4: =IFERROR((AR4-$G4)*AQ4,0) -> 0 | AT4: =交易记录!D455 -> 0 | AU4: =交易记录!D486 -> 0 | AV4: =IFERROR((AU4-$G4)*AT4,0) -> 0 | AW4: =交易记录!D519 -> 0 | AX4: =交易记录!D550 -> 0 | AY4: =IFERROR((AX4-$G4)*AW4,0) -> 0 | AZ4: =交易记录!D583 -> 0 | BA4: =交易记录!D614 -> 0 | BB4: =IFERROR((BA4-$G4)*AZ4,0) -> 0 | BC4: =交易记录!D647 -> 0 | BD4: =交易记录!D678 -> 0 | BE4: =IFERROR((BD4-$G4)*BC4,0) -> 0 | BF4: =交易记录!D711 -> 0 | BG4: =交易记录!D742 -> 0 | BH4: =IFERROR((BG4-$G4)*BF4,0) -> 0 | BI4: =交易记录!D775 -> 0 | BJ4: =交易记录!D806 -> 0 | BK4: =IFERROR((BJ4-$G4)*BI4,0) -> 0 | BL4: =交易记录!D839 -> 0 | BM4: =交易记录!D870 -> 0 | BN4: =IFERROR((BM4-$G4)*BL4,0) -> 0 | BO4: =交易记录!D903 -> 0 | BP4: =交易记录!D934 -> 0 | BQ4: =IFERROR((BP4-$G4)*BO4,0) -> 0
A5: ='维护-日期'!A$3 -> 46266 | B5: 03:00-04:00 | C5: =D5 -> 13.817 | D5: =ROUND(INDEX(持仓数据!$C$3:$AG$26,MATCH('计算过程-数据汇总'!B5,持仓数据!$B$3:$B$26,0),MATCH('计算过程-数据汇总'!A5,'维护-日期'!$B$2:$AF$2,0)),3) -> 13.817 | E5: =D5*1 -> 13.817 | F5: =持仓数据!C75 -> 0.171 | G5: 372 | H5: 372 | I5: 0 | J5: 0 | K5: =IF(持仓数据!C108="",0,持仓数据!C108) -> 372 | L5: =I5*J5 -> 0 | M5: =IFERROR(C5*G5,0) -> 5139.924 | N5: =IFERROR((D5-C5)*(G5-H5),0) -> 0 | O5: =IFERROR((E5-D5)*(G5-H5),0) -> 0 | P5: =IFERROR(F5*(K5-G5),0) -> 0 | Q5: =IFERROR(IF(ABS((E5-C5)/C5)>0.2,IF(SUM(N5:O5)<0,ABS(G5-H5)*(ABS(C5-E5)-C5*0.2),0),0),IF(SUM(N5:O5)<0,ABS(G5-H5)*(ABS(C5-E5)-C5*0.2),0)) -> 0 | R5: =IFERROR(K5*C5,0) -> 5139.924 | S5: =IFERROR((D5-E5)*(K5-G5),0) -> 0 | T5: =IFERROR((F5-D5)*(K5-G5),0) -> 0 | U5: =IFERROR((D5-C5)*(K5-H5),0) -> 0 | V5: =IFERROR((E5-D5)*(K5-H5),0) -> 0 | X5: =ROUND(D5*1.2-SUM(Y5,AB5,AE5,AH5,AK5,AN5,AQ5,AT5,AW5,AZ5,BC5,BF5,BI5,BL5,BO5),3) -> 16.409 | Y5: =交易记录!D8 -> 0.171 | Z5: =交易记录!D39 -> 372 | AA5: =IFERROR((Z5-G5)*Y5,0) -> 0 | AB5: =交易记录!D72 -> 0 | AC5: =交易记录!D103 -> 0 | AD5: =IFERROR((AC5-$G5)*AB5,0) -> 0 | AE5: =交易记录!D136 -> 0 | AF5: =交易记录!D167 -> 0 | AG5: =IFERROR((AF5-$G5)*AE5,0) -> 0 | AH5: =交易记录!D200 -> 0 | AI5: =交易记录!D231 -> 0 | AJ5: =IFERROR((AI5-$G5)*AH5,0) -> 0 | AK5: =交易记录!D264 -> 0 | AL5: =交易记录!D295 -> 0 | AM5: =IFERROR((AL5-$G5)*AK5,0) -> 0 | AN5: =交易记录!D328 -> 0 | AO5: =交易记录!D359 -> 0 | AP5: =IFERROR((AO5-$G5)*AN5,0) -> 0 | AQ5: =交易记录!D392 -> 0 | AR5: =交易记录!D423 -> 0 | AS5: =IFERROR((AR5-$G5)*AQ5,0) -> 0 | AT5: =交易记录!D456 -> 0 | AU5: =交易记录!D487 -> 0 | AV5: =IFERROR((AU5-$G5)*AT5,0) -> 0 | AW5: =交易记录!D520 -> 0 | AX5: =交易记录!D551 -> 0 | AY5: =IFERROR((AX5-$G5)*AW5,0) -> 0 | AZ5: =交易记录!D584 -> 0 | BA5: =交易记录!D615 -> 0 | BB5: =IFERROR((BA5-$G5)*AZ5,0) -> 0 | BC5: =交易记录!D648 -> 0 | BD5: =交易记录!D679 -> 0 | BE5: =IFERROR((BD5-$G5)*BC5,0) -> 0 | BF5: =交易记录!D712 -> 0 | BG5: =交易记录!D743 -> 0 | BH5: =IFERROR((BG5-$G5)*BF5,0) -> 0 | BI5: =交易记录!D776 -> 0 | BJ5: =交易记录!D807 -> 0 | BK5: =IFERROR((BJ5-$G5)*BI5,0) -> 0 | BL5: =交易记录!D840 -> 0 | BM5: =交易记录!D871 -> 0 | BN5: =IFERROR((BM5-$G5)*BL5,0) -> 0 | BO5: =交易记录!D904 -> 0 | BP5: =交易记录!D935 -> 0 | BQ5: =IFERROR((BP5-$G5)*BO5,0) -> 0
A6: ='维护-日期'!A$3 -> 46266 | B6: 04:00-05:00 | C6: =D6 -> 13.388 | D6: =ROUND(INDEX(持仓数据!$C$3:$AG$26,MATCH('计算过程-数据汇总'!B6,持仓数据!$B$3:$B$26,0),MATCH('计算过程-数据汇总'!A6,'维护-日期'!$B$2:$AF$2,0)),3) -> 13.388 | E6: =D6*1 -> 13.388 | F6: =持仓数据!C76 -> 0.074 | G6: 372 | H6: 372 | I6: 0 | J6: 0 | K6: =IF(持仓数据!C109="",0,持仓数据!C109) -> 372 | L6: =I6*J6 -> 0 | M6: =IFERROR(C6*G6,0) -> 4980.336 | N6: =IFERROR((D6-C6)*(G6-H6),0) -> 0 | O6: =IFERROR((E6-D6)*(G6-H6),0) -> 0 | P6: =IFERROR(F6*(K6-G6),0) -> 0 | Q6: =IFERROR(IF(ABS((E6-C6)/C6)>0.2,IF(SUM(N6:O6)<0,ABS(G6-H6)*(ABS(C6-E6)-C6*0.2),0),0),IF(SUM(N6:O6)<0,ABS(G6-H6)*(ABS(C6-E6)-C6*0.2),0)) -> 0 | R6: =IFERROR(K6*C6,0) -> 4980.336 | S6: =IFERROR((D6-E6)*(K6-G6),0) -> 0 | T6: =IFERROR((F6-D6)*(K6-G6),0) -> 0 | U6: =IFERROR((D6-C6)*(K6-H6),0) -> 0 | V6: =IFERROR((E6-D6)*(K6-H6),0) -> 0 | X6: =ROUND(D6*1.2-SUM(Y6,AB6,AE6,AH6,AK6,AN6,AQ6,AT6,AW6,AZ6,BC6,BF6,BI6,BL6,BO6),3) -> 15.992 | Y6: =交易记录!D9 -> 0.074 | Z6: =交易记录!D40 -> 372 | AA6: =IFERROR((Z6-G6)*Y6,0) -> 0 | AB6: =交易记录!D73 -> 0 | AC6: =交易记录!D104 -> 0 | AD6: =IFERROR((AC6-$G6)*AB6,0) -> 0 | AE6: =交易记录!D137 -> 0 | AF6: =交易记录!D168 -> 0 | AG6: =IFERROR((AF6-$G6)*AE6,0) -> 0 | AH6: =交易记录!D201 -> 0 | AI6: =交易记录!D232 -> 0 | AJ6: =IFERROR((AI6-$G6)*AH6,0) -> 0 | AK6: =交易记录!D265 -> 0 | AL6: =交易记录!D296 -> 0 | AM6: =IFERROR((AL6-$G6)*AK6,0) -> 0 | AN6: =交易记录!D329 -> 0 | AO6: =交易记录!D360 -> 0 | AP6: =IFERROR((AO6-$G6)*AN6,0) -> 0 | AQ6: =交易记录!D393 -> 0 | AR6: =交易记录!D424 -> 0 | AS6: =IFERROR((AR6-$G6)*AQ6,0) -> 0 | AT6: =交易记录!D457 -> 0 | AU6: =交易记录!D488 -> 0 | AV6: =IFERROR((AU6-$G6)*AT6,0) -> 0 | AW6: =交易记录!D521 -> 0 | AX6: =交易记录!D552 -> 0 | AY6: =IFERROR((AX6-$G6)*AW6,0) -> 0 | AZ6: =交易记录!D585 -> 0 | BA6: =交易记录!D616 -> 0 | BB6: =IFERROR((BA6-$G6)*AZ6,0) -> 0 | BC6: =交易记录!D649 -> 0 | BD6: =交易记录!D680 -> 0 | BE6: =IFERROR((BD6-$G6)*BC6,0) -> 0 | BF6: =交易记录!D713 -> 0 | BG6: =交易记录!D744 -> 0 | BH6: =IFERROR((BG6-$G6)*BF6,0) -> 0 | BI6: =交易记录!D777 -> 0 | BJ6: =交易记录!D808 -> 0 | BK6: =IFERROR((BJ6-$G6)*BI6,0) -> 0 | BL6: =交易记录!D841 -> 0 | BM6: =交易记录!D872 -> 0 | BN6: =IFERROR((BM6-$G6)*BL6,0) -> 0 | BO6: =交易记录!D905 -> 0 | BP6: =交易记录!D936 -> 0 | BQ6: =IFERROR((BP6-$G6)*BO6,0) -> 0
A7: ='维护-日期'!A$3 -> 46266 | B7: 05:00-06:00 | C7: =D7 -> 13.087 | D7: =ROUND(INDEX(持仓数据!$C$3:$AG$26,MATCH('计算过程-数据汇总'!B7,持仓数据!$B$3:$B$26,0),MATCH('计算过程-数据汇总'!A7,'维护-日期'!$B$2:$AF$2,0)),3) -> 13.087 | E7: =D7*1 -> 13.087 | F7: =持仓数据!C77 -> 0.072 | G7: 372 | H7: 372 | I7: 0 | J7: 0 | K7: =IF(持仓数据!C110="",0,持仓数据!C110) -> 372 | L7: =I7*J7 -> 0 | M7: =IFERROR(C7*G7,0) -> 4868.364 | N7: =IFERROR((D7-C7)*(G7-H7),0) -> 0 | O7: =IFERROR((E7-D7)*(G7-H7),0) -> 0 | P7: =IFERROR(F7*(K7-G7),0) -> 0 | Q7: =IFERROR(IF(ABS((E7-C7)/C7)>0.2,IF(SUM(N7:O7)<0,ABS(G7-H7)*(ABS(C7-E7)-C7*0.2),0),0),IF(SUM(N7:O7)<0,ABS(G7-H7)*(ABS(C7-E7)-C7*0.2),0)) -> 0 | R7: =IFERROR(K7*C7,0) -> 4868.364 | S7: =IFERROR((D7-E7)*(K7-G7),0) -> 0 | T7: =IFERROR((F7-D7)*(K7-G7),0) -> 0 | U7: =IFERROR((D7-C7)*(K7-H7),0) -> 0 | V7: =IFERROR((E7-D7)*(K7-H7),0) -> 0 | X7: =ROUND(D7*1.2-SUM(Y7,AB7,AE7,AH7,AK7,AN7,AQ7,AT7,AW7,AZ7,BC7,BF7,BI7,BL7,BO7),3) -> 15.632 | Y7: =交易记录!D10 -> 0.072 | Z7: =交易记录!D41 -> 372 | AA7: =IFERROR((Z7-G7)*Y7,0) -> 0 | AB7: =交易记录!D74 -> 0 | AC7: =交易记录!D105 -> 0 | AD7: =IFERROR((AC7-$G7)*AB7,0) -> 0 | AE7: =交易记录!D138 -> 0 | AF7: =交易记录!D169 -> 0 | AG7: =IFERROR((AF7-$G7)*AE7,0) -> 0 | AH7: =交易记录!D202 -> 0 | AI7: =交易记录!D233 -> 0 | AJ7: =IFERROR((AI7-$G7)*AH7,0) -> 0 | AK7: =交易记录!D266 -> 0 | AL7: =交易记录!D297 -> 0 | AM7: =IFERROR((AL7-$G7)*AK7,0) -> 0 | AN7: =交易记录!D330 -> 0 | AO7: =交易记录!D361 -> 0 | AP7: =IFERROR((AO7-$G7)*AN7,0) -> 0 | AQ7: =交易记录!D394 -> 0 | AR7: =交易记录!D425 -> 0 | AS7: =IFERROR((AR7-$G7)*AQ7,0) -> 0 | AT7: =交易记录!D458 -> 0 | AU7: =交易记录!D489 -> 0 | AV7: =IFERROR((AU7-$G7)*AT7,0) -> 0 | AW7: =交易记录!D522 -> 0 | AX7: =交易记录!D553 -> 0 | AY7: =IFERROR((AX7-$G7)*AW7,0) -> 0 | AZ7: =交易记录!D586 -> 0 | BA7: =交易记录!D617 -> 0 | BB7: =IFERROR((BA7-$G7)*AZ7,0) -> 0 | BC7: =交易记录!D650 -> 0 | BD7: =交易记录!D681 -> 0 | BE7: =IFERROR((BD7-$G7)*BC7,0) -> 0 | BF7: =交易记录!D714 -> 0 | BG7: =交易记录!D745 -> 0 | BH7: =IFERROR((BG7-$G7)*BF7,0) -> 0 | BI7: =交易记录!D778 -> 0 | BJ7: =交易记录!D809 -> 0 | BK7: =IFERROR((BJ7-$G7)*BI7,0) -> 0 | BL7: =交易记录!D842 -> 0 | BM7: =交易记录!D873 -> 0 | BN7: =IFERROR((BM7-$G7)*BL7,0) -> 0 | BO7: =交易记录!D906 -> 0 | BP7: =交易记录!D937 -> 0 | BQ7: =IFERROR((BP7-$G7)*BO7,0) -> 0
A8: ='维护-日期'!A$3 -> 46266 | B8: 06:00-07:00 | C8: =D8 -> 12.95 | D8: =ROUND(INDEX(持仓数据!$C$3:$AG$26,MATCH('计算过程-数据汇总'!B8,持仓数据!$B$3:$B$26,0),MATCH('计算过程-数据汇总'!A8,'维护-日期'!$B$2:$AF$2,0)),3) -> 12.95 | E8: =D8*1 -> 12.95 | F8: =持仓数据!C78 -> 0.118 | G8: 372 | H8: 372 | I8: 0 | J8: 0 | K8: =IF(持仓数据!C111="",0,持仓数据!C111) -> 372 | L8: =I8*J8 -> 0 | M8: =IFERROR(C8*G8,0) -> 4817.4 | N8: =IFERROR((D8-C8)*(G8-H8),0) -> 0 | O8: =IFERROR((E8-D8)*(G8-H8),0) -> 0 | P8: =IFERROR(F8*(K8-G8),0) -> 0 | Q8: =IFERROR(IF(ABS((E8-C8)/C8)>0.2,IF(SUM(N8:O8)<0,ABS(G8-H8)*(ABS(C8-E8)-C8*0.2),0),0),IF(SUM(N8:O8)<0,ABS(G8-H8)*(ABS(C8-E8)-C8*0.2),0)) -> 0 | R8: =IFERROR(K8*C8,0) -> 4817.4 | S8: =IFERROR((D8-E8)*(K8-G8),0) -> 0 | T8: =IFERROR((F8-D8)*(K8-G8),0) -> 0 | U8: =IFERROR((D8-C8)*(K8-H8),0) -> 0 | V8: =IFERROR((E8-D8)*(K8-H8),0) -> 0 | X8: =ROUND(D8*1.2-SUM(Y8,AB8,AE8,AH8,AK8,AN8,AQ8,AT8,AW8,AZ8,BC8,BF8,BI8,BL8,BO8),3) -> 15.422 | Y8: =交易记录!D11 -> 0.118 | Z8: =交易记录!D42 -> 372 | AA8: =IFERROR((Z8-G8)*Y8,0) -> 0 | AB8: =交易记录!D75 -> 0 | AC8: =交易记录!D106 -> 0 | AD8: =IFERROR((AC8-$G8)*AB8,0) -> 0 | AE8: =交易记录!D139 -> 0 | AF8: =交易记录!D170 -> 0 | AG8: =IFERROR((AF8-$G8)*AE8,0) -> 0 | AH8: =交易记录!D203 -> 0 | AI8: =交易记录!D234 -> 0 | AJ8: =IFERROR((AI8-$G8)*AH8,0) -> 0 | AK8: =交易记录!D267 -> 0 | AL8: =交易记录!D298 -> 0 | AM8: =IFERROR((AL8-$G8)*AK8,0) -> 0 | AN8: =交易记录!D331 -> 0 | AO8: =交易记录!D362 -> 0 | AP8: =IFERROR((AO8-$G8)*AN8,0) -> 0 | AQ8: =交易记录!D395 -> 0 | AR8: =交易记录!D426 -> 0 | AS8: =IFERROR((AR8-$G8)*AQ8,0) -> 0 | AT8: =交易记录!D459 -> 0 | AU8: =交易记录!D490 -> 0 | AV8: =IFERROR((AU8-$G8)*AT8,0) -> 0 | AW8: =交易记录!D523 -> 0 | AX8: =交易记录!D554 -> 0 | AY8: =IFERROR((AX8-$G8)*AW8,0) -> 0 | AZ8: =交易记录!D587 -> 0 | BA8: =交易记录!D618 -> 0 | BB8: =IFERROR((BA8-$G8)*AZ8,0) -> 0 | BC8: =交易记录!D651 -> 0 | BD8: =交易记录!D682 -> 0 | BE8: =IFERROR((BD8-$G8)*BC8,0) -> 0 | BF8: =交易记录!D715 -> 0 | BG8: =交易记录!D746 -> 0 | BH8: =IFERROR((BG8-$G8)*BF8,0) -> 0 | BI8: =交易记录!D779 -> 0 | BJ8: =交易记录!D810 -> 0 | BK8: =IFERROR((BJ8-$G8)*BI8,0) -> 0 | BL8: =交易记录!D843 -> 0 | BM8: =交易记录!D874 -> 0 | BN8: =IFERROR((BM8-$G8)*BL8,0) -> 0 | BO8: =交易记录!D907 -> 0 | BP8: =交易记录!D938 -> 0 | BQ8: =IFERROR((BP8-$G8)*BO8,0) -> 0
A9: ='维护-日期'!A$3 -> 46266 | B9: 07:00-08:00 | C9: =D9 -> 13.267 | D9: =ROUND(INDEX(持仓数据!$C$3:$AG$26,MATCH('计算过程-数据汇总'!B9,持仓数据!$B$3:$B$26,0),MATCH('计算过程-数据汇总'!A9,'维护-日期'!$B$2:$AF$2,0)),3) -> 13.267 | E9: =D9*1 -> 13.267 | F9: =持仓数据!C79 -> 0.135 | G9: 372 | H9: 372 | I9: 0 | J9: 0 | K9: =IF(持仓数据!C112="",0,持仓数据!C112) -> 372 | L9: =I9*J9 -> 0 | M9: =IFERROR(C9*G9,0) -> 4935.324 | N9: =IFERROR((D9-C9)*(G9-H9),0) -> 0 | O9: =IFERROR((E9-D9)*(G9-H9),0) -> 0 | P9: =IFERROR(F9*(K9-G9),0) -> 0 | Q9: =IFERROR(IF(ABS((E9-C9)/C9)>0.2,IF(SUM(N9:O9)<0,ABS(G9-H9)*(ABS(C9-E9)-C9*0.2),0),0),IF(SUM(N9:O9)<0,ABS(G9-H9)*(ABS(C9-E9)-C9*0.2),0)) -> 0 | R9: =IFERROR(K9*C9,0) -> 4935.324 | S9: =IFERROR((D9-E9)*(K9-G9),0) -> 0 | T9: =IFERROR((F9-D9)*(K9-G9),0) -> 0 | U9: =IFERROR((D9-C9)*(K9-H9),0) -> 0 | V9: =IFERROR((E9-D9)*(K9-H9),0) -> 0 | X9: =ROUND(D9*1.2-SUM(Y9,AB9,AE9,AH9,AK9,AN9,AQ9,AT9,AW9,AZ9,BC9,BF9,BI9,BL9,BO9),3) -> 15.785 | Y9: =交易记录!D12 -> 0.135 | Z9: =交易记录!D43 -> 372 | AA9: =IFERROR((Z9-G9)*Y9,0) -> 0 | AB9: =交易记录!D76 -> 0 | AC9: =交易记录!D107 -> 0 | AD9: =IFERROR((AC9-$G9)*AB9,0) -> 0 | AE9: =交易记录!D140 -> 0 | AF9: =交易记录!D171 -> 0 | AG9: =IFERROR((AF9-$G9)*AE9,0) -> 0 | AH9: =交易记录!D204 -> 0 | AI9: =交易记录!D235 -> 0 | AJ9: =IFERROR((AI9-$G9)*AH9,0) -> 0 | AK9: =交易记录!D268 -> 0 | AL9: =交易记录!D299 -> 0 | AM9: =IFERROR((AL9-$G9)*AK9,0) -> 0 | AN9: =交易记录!D332 -> 0 | AO9: =交易记录!D363 -> 0 | AP9: =IFERROR((AO9-$G9)*AN9,0) -> 0 | AQ9: =交易记录!D396 -> 0 | AR9: =交易记录!D427 -> 0 | AS9: =IFERROR((AR9-$G9)*AQ9,0) -> 0 | AT9: =交易记录!D460 -> 0 | AU9: =交易记录!D491 -> 0 | AV9: =IFERROR((AU9-$G9)*AT9,0) -> 0 | AW9: =交易记录!D524 -> 0 | AX9: =交易记录!D555 -> 0 | AY9: =IFERROR((AX9-$G9)*AW9,0) -> 0 | AZ9: =交易记录!D588 -> 0 | BA9: =交易记录!D619 -> 0 | BB9: =IFERROR((BA9-$G9)*AZ9,0) -> 0 | BC9: =交易记录!D652 -> 0 | BD9: =交易记录!D683 -> 0 | BE9: =IFERROR((BD9-$G9)*BC9,0) -> 0 | BF9: =交易记录!D716 -> 0 | BG9: =交易记录!D747 -> 0 | BH9: =IFERROR((BG9-$G9)*BF9,0) -> 0 | BI9: =交易记录!D780 -> 0 | BJ9: =交易记录!D811 -> 0 | BK9: =IFERROR((BJ9-$G9)*BI9,0) -> 0 | BL9: =交易记录!D844 -> 0 | BM9: =交易记录!D875 -> 0 | BN9: =IFERROR((BM9-$G9)*BL9,0) -> 0 | BO9: =交易记录!D908 -> 0 | BP9: =交易记录!D939 -> 0 | BQ9: =IFERROR((BP9-$G9)*BO9,0) -> 0
A10: ='维护-日期'!A$3 -> 46266 | B10: 08:00-09:00 | C10: =D10 -> 15.796 | D10: =ROUND(INDEX(持仓数据!$C$3:$AG$26,MATCH('计算过程-数据汇总'!B10,持仓数据!$B$3:$B$26,0),MATCH('计算过程-数据汇总'!A10,'维护-日期'!$B$2:$AF$2,0)),3) -> 15.796 | E10: =D10*1 -> 15.796 | F10: =持仓数据!C80 -> 0.261 | G10: 372 | H10: 372 | I10: 0 | J10: 0 | K10: =IF(持仓数据!C113="",0,持仓数据!C113) -> 372 | L10: =I10*J10 -> 0 | M10: =IFERROR(C10*G10,0) -> 5876.112 | N10: =IFERROR((D10-C10)*(G10-H10),0) -> 0 | O10: =IFERROR((E10-D10)*(G10-H10),0) -> 0 | P10: =IFERROR(F10*(K10-G10),0) -> 0 | Q10: =IFERROR(IF(ABS((E10-C10)/C10)>0.2,IF(SUM(N10:O10)<0,ABS(G10-H10)*(ABS(C10-E10)-C10*0.2),0),0),IF(SUM(N10:O10)<0,ABS(G10-H10)*(ABS(C10-E10)-C10*0.2),0)) -> 0 | R10: =IFERROR(K10*C10,0) -> 5876.112 | S10: =IFERROR((D10-E10)*(K10-G10),0) -> 0 | T10: =IFERROR((F10-D10)*(K10-G10),0) -> 0 | U10: =IFERROR((D10-C10)*(K10-H10),0) -> 0 | V10: =IFERROR((E10-D10)*(K10-H10),0) -> 0 | X10: =ROUND(D10*1.2-SUM(Y10,AB10,AE10,AH10,AK10,AN10,AQ10,AT10,AW10,AZ10,BC10,BF10,BI10,BL10,BO10),3) -> 18.694 | Y10: =交易记录!D13 -> 0.261 | Z10: =交易记录!D44 -> 372 | AA10: =IFERROR((Z10-G10)*Y10,0) -> 0 | AB10: =交易记录!D77 -> 0 | AC10: =交易记录!D108 -> 0 | AD10: =IFERROR((AC10-$G10)*AB10,0) -> 0 | AE10: =交易记录!D141 -> 0 | AF10: =交易记录!D172 -> 0 | AG10: =IFERROR((AF10-$G10)*AE10,0) -> 0 | AH10: =交易记录!D205 -> 0 | AI10: =交易记录!D236 -> 0 | AJ10: =IFERROR((AI10-$G10)*AH10,0) -> 0 | AK10: =交易记录!D269 -> 0 | AL10: =交易记录!D300 -> 0 | AM10: =IFERROR((AL10-$G10)*AK10,0) -> 0 | AN10: =交易记录!D333 -> 0 | AO10: =交易记录!D364 -> 0 | AP10: =IFERROR((AO10-$G10)*AN10,0) -> 0 | AQ10: =交易记录!D397 -> 0 | AR10: =交易记录!D428 -> 0 | AS10: =IFERROR((AR10-$G10)*AQ10,0) -> 0 | AT10: =交易记录!D461 -> 0 | AU10: =交易记录!D492 -> 0 | AV10: =IFERROR((AU10-$G10)*AT10,0) -> 0 | AW10: =交易记录!D525 -> 0 | AX10: =交易记录!D556 -> 0 | AY10: =IFERROR((AX10-$G10)*AW10,0) -> 0 | AZ10: =交易记录!D589 -> 0 | BA10: =交易记录!D620 -> 0 | BB10: =IFERROR((BA10-$G10)*AZ10,0) -> 0 | BC10: =交易记录!D653 -> 0 | BD10: =交易记录!D684 -> 0 | BE10: =IFERROR((BD10-$G10)*BC10,0) -> 0 | BF10: =交易记录!D717 -> 0 | BG10: =交易记录!D748 -> 0 | BH10: =IFERROR((BG10-$G10)*BF10,0) -> 0 | BI10: =交易记录!D781 -> 0 | BJ10: =交易记录!D812 -> 0 | BK10: =IFERROR((BJ10-$G10)*BI10,0) -> 0 | BL10: =交易记录!D845 -> 0 | BM10: =交易记录!D876 -> 0 | BN10: =IFERROR((BM10-$G10)*BL10,0) -> 0 | BO10: =交易记录!D909 -> 0 | BP10: =交易记录!D940 -> 0 | BQ10: =IFERROR((BP10-$G10)*BO10,0) -> 0
A11: ='维护-日期'!A$3 -> 46266 | B11: 09:00-10:00 | C11: =D11 -> 19.308 | D11: =ROUND(INDEX(持仓数据!$C$3:$AG$26,MATCH('计算过程-数据汇总'!B11,持仓数据!$B$3:$B$26,0),MATCH('计算过程-数据汇总'!A11,'维护-日期'!$B$2:$AF$2,0)),3) -> 19.308 | E11: =D11*1 -> 19.308 | F11: =持仓数据!C81 -> 0.28 | G11: 372 | H11: 372 | I11: 0 | J11: 0 | K11: =IF(持仓数据!C114="",0,持仓数据!C114) -> 372 | L11: =I11*J11 -> 0 | M11: =IFERROR(C11*G11,0) -> 7182.576 | N11: =IFERROR((D11-C11)*(G11-H11),0) -> 0 | O11: =IFERROR((E11-D11)*(G11-H11),0) -> 0 | P11: =IFERROR(F11*(K11-G11),0) -> 0 | Q11: =IFERROR(IF(ABS((E11-C11)/C11)>0.2,IF(SUM(N11:O11)<0,ABS(G11-H11)*(ABS(C11-E11)-C11*0.2),0),0),IF(SUM(N11:O11)<0,ABS(G11-H11)*(ABS(C11-E11)-C11*0.2),0)) -> 0 | R11: =IFERROR(K11*C11,0) -> 7182.576 | S11: =IFERROR((D11-E11)*(K11-G11),0) -> 0 | T11: =IFERROR((F11-D11)*(K11-G11),0) -> 0 | U11: =IFERROR((D11-C11)*(K11-H11),0) -> 0 | V11: =IFERROR((E11-D11)*(K11-H11),0) -> 0 | X11: =ROUND(D11*1.2-SUM(Y11,AB11,AE11,AH11,AK11,AN11,AQ11,AT11,AW11,AZ11,BC11,BF11,BI11,BL11,BO11),3) -> 22.89 | Y11: =交易记录!D14 -> 0.28 | Z11: =交易记录!D45 -> 372 | AA11: =IFERROR((Z11-G11)*Y11,0) -> 0 | AB11: =交易记录!D78 -> 0 | AC11: =交易记录!D109 -> 0 | AD11: =IFERROR((AC11-$G11)*AB11,0) -> 0 | AE11: =交易记录!D142 -> 0 | AF11: =交易记录!D173 -> 0 | AG11: =IFERROR((AF11-$G11)*AE11,0) -> 0 | AH11: =交易记录!D206 -> 0 | AI11: =交易记录!D237 -> 0 | AJ11: =IFERROR((AI11-$G11)*AH11,0) -> 0 | AK11: =交易记录!D270 -> 0 | AL11: =交易记录!D301 -> 0 | AM11: =IFERROR((AL11-$G11)*AK11,0) -> 0 | AN11: =交易记录!D334 -> 0 | AO11: =交易记录!D365 -> 0 | AP11: =IFERROR((AO11-$G11)*AN11,0) -> 0 | AQ11: =交易记录!D398 -> 0 | AR11: =交易记录!D429 -> 0 | AS11: =IFERROR((AR11-$G11)*AQ11,0) -> 0 | AT11: =交易记录!D462 -> 0 | AU11: =交易记录!D493 -> 0 | AV11: =IFERROR((AU11-$G11)*AT11,0) -> 0 | AW11: =交易记录!D526 -> 0 | AX11: =交易记录!D557 -> 0 | AY11: =IFERROR((AX11-$G11)*AW11,0) -> 0 | AZ11: =交易记录!D590 -> 0 | BA11: =交易记录!D621 -> 0 | BB11: =IFERROR((BA11-$G11)*AZ11,0) -> 0 | BC11: =交易记录!D654 -> 0 | BD11: =交易记录!D685 -> 0 | BE11: =IFERROR((BD11-$G11)*BC11,0) -> 0 | BF11: =交易记录!D718 -> 0 | BG11: =交易记录!D749 -> 0 | BH11: =IFERROR((BG11-$G11)*BF11,0) -> 0 | BI11: =交易记录!D782 -> 0 | BJ11: =交易记录!D813 -> 0 | BK11: =IFERROR((BJ11-$G11)*BI11,0) -> 0 | BL11: =交易记录!D846 -> 0 | BM11: =交易记录!D877 -> 0 | BN11: =IFERROR((BM11-$G11)*BL11,0) -> 0 | BO11: =交易记录!D910 -> 0 | BP11: =交易记录!D941 -> 0 | BQ11: =IFERROR((BP11-$G11)*BO11,0) -> 0
A12: ='维护-日期'!A$3 -> 46266 | B12: 10:00-11:00 | C12: =D12 -> 21.01 | D12: =ROUND(INDEX(持仓数据!$C$3:$AG$26,MATCH('计算过程-数据汇总'!B12,持仓数据!$B$3:$B$26,0),MATCH('计算过程-数据汇总'!A12,'维护-日期'!$B$2:$AF$2,0)),3) -> 21.01 | E12: =D12*1 -> 21.01 | F12: =持仓数据!C82 -> 0.284 | G12: 372 | H12: 372 | I12: 0 | J12: 0 | K12: =IF(持仓数据!C115="",0,持仓数据!C115) -> 372 | L12: =I12*J12 -> 0 | M12: =IFERROR(C12*G12,0) -> 7815.72 | N12: =IFERROR((D12-C12)*(G12-H12),0) -> 0 | O12: =IFERROR((E12-D12)*(G12-H12),0) -> 0 | P12: =IFERROR(F12*(K12-G12),0) -> 0 | Q12: =IFERROR(IF(ABS((E12-C12)/C12)>0.2,IF(SUM(N12:O12)<0,ABS(G12-H12)*(ABS(C12-E12)-C12*0.2),0),0),IF(SUM(N12:O12)<0,ABS(G12-H12)*(ABS(C12-E12)-C12*0.2),0)) -> 0 | R12: =IFERROR(K12*C12,0) -> 7815.72 | S12: =IFERROR((D12-E12)*(K12-G12),0) -> 0 | T12: =IFERROR((F12-D12)*(K12-G12),0) -> 0 | U12: =IFERROR((D12-C12)*(K12-H12),0) -> 0 | V12: =IFERROR((E12-D12)*(K12-H12),0) -> 0 | X12: =ROUND(D12*1.2-SUM(Y12,AB12,AE12,AH12,AK12,AN12,AQ12,AT12,AW12,AZ12,BC12,BF12,BI12,BL12,BO12),3) -> 24.928 | Y12: =交易记录!D15 -> 0.284 | Z12: =交易记录!D46 -> 372 | AA12: =IFERROR((Z12-G12)*Y12,0) -> 0 | AB12: =交易记录!D79 -> 0 | AC12: =交易记录!D110 -> 0 | AD12: =IFERROR((AC12-$G12)*AB12,0) -> 0 | AE12: =交易记录!D143 -> 0 | AF12: =交易记录!D174 -> 0 | AG12: =IFERROR((AF12-$G12)*AE12,0) -> 0 | AH12: =交易记录!D207 -> 0 | AI12: =交易记录!D238 -> 0 | AJ12: =IFERROR((AI12-$G12)*AH12,0) -> 0 | AK12: =交易记录!D271 -> 0 | AL12: =交易记录!D302 -> 0 | AM12: =IFERROR((AL12-$G12)*AK12,0) -> 0 | AN12: =交易记录!D335 -> 0 | AO12: =交易记录!D366 -> 0 | AP12: =IFERROR((AO12-$G12)*AN12,0) -> 0 | AQ12: =交易记录!D399 -> 0 | AR12: =交易记录!D430 -> 0 | AS12: =IFERROR((AR12-$G12)*AQ12,0) -> 0 | AT12: =交易记录!D463 -> 0 | AU12: =交易记录!D494 -> 0 | AV12: =IFERROR((AU12-$G12)*AT12,0) -> 0 | AW12: =交易记录!D527 -> 0 | AX12: =交易记录!D558 -> 0 | AY12: =IFERROR((AX12-$G12)*AW12,0) -> 0 | AZ12: =交易记录!D591 -> 0 | BA12: =交易记录!D622 -> 0 | BB12: =IFERROR((BA12-$G12)*AZ12,0) -> 0 | BC12: =交易记录!D655 -> 0 | BD12: =交易记录!D686 -> 0 | BE12: =IFERROR((BD12-$G12)*BC12,0) -> 0 | BF12: =交易记录!D719 -> 0 | BG12: =交易记录!D750 -> 0 | BH12: =IFERROR((BG12-$G12)*BF12,0) -> 0 | BI12: =交易记录!D783 -> 0 | BJ12: =交易记录!D814 -> 0 | BK12: =IFERROR((BJ12-$G12)*BI12,0) -> 0 | BL12: =交易记录!D847 -> 0 | BM12: =交易记录!D878 -> 0 | BN12: =IFERROR((BM12-$G12)*BL12,0) -> 0 | BO12: =交易记录!D911 -> 0 | BP12: =交易记录!D942 -> 0 | BQ12: =IFERROR((BP12-$G12)*BO12,0) -> 0
A13: ='维护-日期'!A$3 -> 46266 | B13: 11:00-12:00 | C13: =D13 -> 21.329 | D13: =ROUND(INDEX(持仓数据!$C$3:$AG$26,MATCH('计算过程-数据汇总'!B13,持仓数据!$B$3:$B$26,0),MATCH('计算过程-数据汇总'!A13,'维护-日期'!$B$2:$AF$2,0)),3) -> 21.329 | E13: =D13*1 -> 21.329 | F13: =持仓数据!C83 -> 0.284 | G13: 372 | H13: 372 | I13: 0 | J13: 0 | K13: =IF(持仓数据!C116="",0,持仓数据!C116) -> 372 | L13: =I13*J13 -> 0 | M13: =IFERROR(C13*G13,0) -> 7934.388 | N13: =IFERROR((D13-C13)*(G13-H13),0) -> 0 | O13: =IFERROR((E13-D13)*(G13-H13),0) -> 0 | P13: =IFERROR(F13*(K13-G13),0) -> 0 | Q13: =IFERROR(IF(ABS((E13-C13)/C13)>0.2,IF(SUM(N13:O13)<0,ABS(G13-H13)*(ABS(C13-E13)-C13*0.2),0),0),IF(SUM(N13:O13)<0,ABS(G13-H13)*(ABS(C13-E13)-C13*0.2),0)) -> 0 | R13: =IFERROR(K13*C13,0) -> 7934.388 | S13: =IFERROR((D13-E13)*(K13-G13),0) -> 0 | T13: =IFERROR((F13-D13)*(K13-G13),0) -> 0 | U13: =IFERROR((D13-C13)*(K13-H13),0) -> 0 | V13: =IFERROR((E13-D13)*(K13-H13),0) -> 0 | X13: =ROUND(D13*1.2-SUM(Y13,AB13,AE13,AH13,AK13,AN13,AQ13,AT13,AW13,AZ13,BC13,BF13,BI13,BL13,BO13),3) -> 25.311 | Y13: =交易记录!D16 -> 0.284 | Z13: =交易记录!D47 -> 372 | AA13: =IFERROR((Z13-G13)*Y13,0) -> 0 | AB13: =交易记录!D80 -> 0 | AC13: =交易记录!D111 -> 0 | AD13: =IFERROR((AC13-$G13)*AB13,0) -> 0 | AE13: =交易记录!D144 -> 0 | AF13: =交易记录!D175 -> 0 | AG13: =IFERROR((AF13-$G13)*AE13,0) -> 0 | AH13: =交易记录!D208 -> 0 | AI13: =交易记录!D239 -> 0 | AJ13: =IFERROR((AI13-$G13)*AH13,0) -> 0 | AK13: =交易记录!D272 -> 0 | AL13: =交易记录!D303 -> 0 | AM13: =IFERROR((AL13-$G13)*AK13,0) -> 0 | AN13: =交易记录!D336 -> 0 | AO13: =交易记录!D367 -> 0 | AP13: =IFERROR((AO13-$G13)*AN13,0) -> 0 | AQ13: =交易记录!D400 -> 0 | AR13: =交易记录!D431 -> 0 | AS13: =IFERROR((AR13-$G13)*AQ13,0) -> 0 | AT13: =交易记录!D464 -> 0 | AU13: =交易记录!D495 -> 0 | AV13: =IFERROR((AU13-$G13)*AT13,0) -> 0 | AW13: =交易记录!D528 -> 0 | AX13: =交易记录!D559 -> 0 | AY13: =IFERROR((AX13-$G13)*AW13,0) -> 0 | AZ13: =交易记录!D592 -> 0 | BA13: =交易记录!D623 -> 0 | BB13: =IFERROR((BA13-$G13)*AZ13,0) -> 0 | BC13: =交易记录!D656 -> 0 | BD13: =交易记录!D687 -> 0 | BE13: =IFERROR((BD13-$G13)*BC13,0) -> 0 | BF13: =交易记录!D720 -> 0 | BG13: =交易记录!D751 -> 0 | BH13: =IFERROR((BG13-$G13)*BF13,0) -> 0 | BI13: =交易记录!D784 -> 0 | BJ13: =交易记录!D815 -> 0 | BK13: =IFERROR((BJ13-$G13)*BI13,0) -> 0 | BL13: =交易记录!D848 -> 0 | BM13: =交易记录!D879 -> 0 | BN13: =IFERROR((BM13-$G13)*BL13,0) -> 0 | BO13: =交易记录!D912 -> 0 | BP13: =交易记录!D943 -> 0 | BQ13: =IFERROR((BP13-$G13)*BO13,0) -> 0
... A25: ='维护-日期'!A$3 -> 46266 | B25: 23:00-24:00 | C25: =D25 -> 16.963 | D25: =ROUND(INDEX(持仓数据!$C$3:$AG$26,MATCH('计算过程-数据汇总'!B25,持仓数据!$B$3:$B$26,0),MATCH('计算过程-数据汇总'!A25,'维护-日期'!$B$2:$AF$2,0)),3) -> 16.963 | E25: =D25*1 -> 16.963 | F25: =持仓数据!C95 -> 0.318 | G25: 372 | H25: 372 | I25: 0 | J25: 0 | K25: =IF(持仓数据!C128="",0,持仓数据!C128) -> 372 | L25: =I25*J25 -> 0 | M25: =IFERROR(C25*G25,0) -> 6310.236 | N25: =IFERROR((D25-C25)*(G25-H25),0) -> 0 | O25: =IFERROR((E25-D25)*(G25-H25),0) -> 0 | P25: =IFERROR(F25*(K25-G25),0) -> 0 | Q25: =IFERROR(IF(ABS((E25-C25)/C25)>0.2,IF(SUM(N25:O25)<0,ABS(G25-H25)*(ABS(C25-E25)-C25*0.2),0),0),IF(SUM(N25:O25)<0,ABS(G25-H25)*(ABS(C25-E25)-C25*0.2),0)) -> 0 | R25: =IFERROR(K25*C25,0) -> 6310.236 | S25: =IFERROR((D25-E25)*(K25-G25),0) -> 0 | T25: =IFERROR((F25-D25)*(K25-G25),0) -> 0 | U25: =IFERROR((D25-C25)*(K25-H25),0) -> 0 | V25: =IFERROR((E25-D25)*(K25-H25),0) -> 0 | X25: =ROUND(D25*1.2-SUM(Y25,AB25,AE25,AH25,AK25,AN25,AQ25,AT25,AW25,AZ25,BC25,BF25,BI25,BL25,BO25),3) -> 20.038 | Y25: =交易记录!D28 -> 0.318 | Z25: =交易记录!D59 -> 372 | AA25: =IFERROR((Z25-G25)*Y25,0) -> 0 | AB25: =交易记录!D92 -> 0 | AC25: =交易记录!D123 -> 0 | AD25: =IFERROR((AC25-$G25)*AB25,0) -> 0 | AE25: =交易记录!D156 -> 0 | AF25: =交易记录!D187 -> 0 | AG25: =IFERROR((AF25-$G25)*AE25,0) -> 0 | AH25: =交易记录!D220 -> 0 | AI25: =交易记录!D251 -> 0 | AJ25: =IFERROR((AI25-$G25)*AH25,0) -> 0 | AK25: =交易记录!D284 -> 0 | AL25: =交易记录!D315 -> 0 | AM25: =IFERROR((AL25-$G25)*AK25,0) -> 0 | AN25: =交易记录!D348 -> 0 | AO25: =交易记录!D379 -> 0 | AP25: =IFERROR((AO25-$G25)*AN25,0) -> 0 | AQ25: =交易记录!D412 -> 0 | AR25: =交易记录!D443 -> 0 | AS25: =IFERROR((AR25-$G25)*AQ25,0) -> 0 | AT25: =交易记录!D476 -> 0 | AU25: =交易记录!D507 -> 0 | AV25: =IFERROR((AU25-$G25)*AT25,0) -> 0 | AW25: =交易记录!D540 -> 0 | AX25: =交易记录!D571 -> 0 | AY25: =IFERROR((AX25-$G25)*AW25,0) -> 0 | AZ25: =交易记录!D604 -> 0 | BA25: =交易记录!D635 -> 0 | BB25: =IFERROR((BA25-$G25)*AZ25,0) -> 0 | BC25: =交易记录!D668 -> 0 | BD25: =交易记录!D699 -> 0 | BE25: =IFERROR((BD25-$G25)*BC25,0) -> 0 | BF25: =交易记录!D732 -> 0 | BG25: =交易记录!D763 -> 0 | BH25: =IFERROR((BG25-$G25)*BF25,0) -> 0 | BI25: =交易记录!D796 -> 0 | BJ25: =交易记录!D827 -> 0 | BK25: =IFERROR((BJ25-$G25)*BI25,0) -> 0 | BL25: =交易记录!D860 -> 0 | BM25: =交易记录!D891 -> 0 | BN25: =IFERROR((BM25-$G25)*BL25,0) -> 0 | BO25: =交易记录!D924 -> 0 | BP25: =交易记录!D955 -> 0 | BQ25: =IFERROR((BP25-$G25)*BO25,0) -> 0
A26: ='维护-日期'!A$4 -> 46267 | B26: 00:00-01:00 | C26: =D26 -> 16.656 | D26: =ROUND(INDEX(持仓数据!$C$3:$AG$26,MATCH('计算过程-数据汇总'!B26,持仓数据!$B$3:$B$26,0),MATCH('计算过程-数据汇总'!A26,'维护-日期'!$B$2:$AF$2,0)),3) -> 16.656 | E26: =D26*1 -> 16.656 | F26: =持仓数据!D72 -> 0.397 | G26: 372 | H26: 372 | I26: 0 | J26: 0 | K26: =IF(持仓数据!D105="",0,持仓数据!D105) -> 372 | L26: =I26*J26 -> 0 | M26: =IFERROR(C26*G26,0) -> 6196.032 | N26: =IFERROR((D26-C26)*(G26-H26),0) -> 0 | O26: =IFERROR((E26-D26)*(G26-H26),0) -> 0 | P26: =IFERROR(F26*(K26-G26),0) -> 0 | Q26: =IFERROR(IF(ABS((E26-C26)/C26)>0.2,IF(SUM(N26:O26)<0,ABS(G26-H26)*(ABS(C26-E26)-C26*0.2),0),0),IF(SUM(N26:O26)<0,ABS(G26-H26)*(ABS(C26-E26)-C26*0.2),0)) -> 0 | R26: =IFERROR(K26*C26,0) -> 6196.032 | S26: =IFERROR((D26-E26)*(K26-G26),0) -> 0 | T26: =IFERROR((F26-D26)*(K26-G26),0) -> 0 | U26: =IFERROR((D26-C26)*(K26-H26),0) -> 0 | V26: =IFERROR((E26-D26)*(K26-H26),0) -> 0 | X26: =ROUND(D26*1.2-SUM(Y26,AB26,AE26,AH26,AK26,AN26,AQ26,AT26,AW26,AZ26,BC26,BF26,BI26,BL26,BO26),3) -> 19.59 | Y26: =交易记录!E5 -> 0.397 | Z26: =交易记录!D36 -> 372 | AA26: =IFERROR((Z26-G26)*Y26,0) -> 0 | AB26: =交易记录!E69 -> 0 | AC26: =交易记录!E100 -> 0 | AD26: =IFERROR((AC26-$G26)*AB26,0) -> 0 | AE26: =交易记录!E133 -> 0 | AF26: =交易记录!E164 -> 0 | AG26: =IFERROR((AF26-$G26)*AE26,0) -> 0 | AH26: =交易记录!E197 -> 0 | AI26: =交易记录!E228 -> 0 | AJ26: =IFERROR((AI26-$G26)*AH26,0) -> 0 | AK26: =交易记录!E261 -> 0 | AL26: =交易记录!E292 -> 0 | AM26: =IFERROR((AL26-$G26)*AK26,0) -> 0 | AN26: =交易记录!E325 -> 0 | AO26: =交易记录!E356 -> 0 | AP26: =IFERROR((AO26-$G26)*AN26,0) -> 0 | AQ26: =交易记录!E389 -> 0 | AR26: =交易记录!D420 -> 0 | AS26: =IFERROR((AR26-$G26)*AQ26,0) -> 0 | AT26: =交易记录!E453 -> 0 | AU26: =交易记录!D484 -> 0 | AV26: =IFERROR((AU26-$G26)*AT26,0) -> 0 | AW26: =交易记录!E517 -> 0 | AX26: =交易记录!D548 -> 0 | AY26: =IFERROR((AX26-$G26)*AW26,0) -> 0 | AZ26: =交易记录!E581 -> 0 | BA26: =交易记录!D612 -> 0 | BB26: =IFERROR((BA26-$G26)*AZ26,0) -> 0 | BC26: =交易记录!E645 -> 0 | BD26: =交易记录!D676 -> 0 | BE26: =IFERROR((BD26-$G26)*BC26,0) -> 0 | BF26: =交易记录!E709 -> 0 | BG26: =交易记录!D740 -> 0 | BH26: =IFERROR((BG26-$G26)*BF26,0) -> 0 | BI26: =交易记录!E773 -> 0 | BJ26: =交易记录!D804 -> 0 | BK26: =IFERROR((BJ26-$G26)*BI26,0) -> 0 | BL26: =交易记录!E837 -> 0 | BM26: =交易记录!D868 -> 0 | BN26: =IFERROR((BM26-$G26)*BL26,0) -> 0 | BO26: =交易记录!E901 -> 0 | BP26: =交易记录!D932 -> 0 | BQ26: =IFERROR((BP26-$G26)*BO26,0) -> 0
A27: ='维护-日期'!A$4 -> 46267 | B27: 01:00-02:00 | C27: =D27 -> 15.792 | D27: =ROUND(INDEX(持仓数据!$C$3:$AG$26,MATCH('计算过程-数据汇总'!B27,持仓数据!$B$3:$B$26,0),MATCH('计算过程-数据汇总'!A27,'维护-日期'!$B$2:$AF$2,0)),3) -> 15.792 | E27: =D27*1 -> 15.792 | F27: =持仓数据!D73 -> 0.265 | G27: 372 | H27: 372 | I27: 0 | J27: 0 | K27: =IF(持仓数据!D106="",0,持仓数据!D106) -> 372 | L27: =I27*J27 -> 0 | M27: =IFERROR(C27*G27,0) -> 5874.624 | N27: =IFERROR((D27-C27)*(G27-H27),0) -> 0 | O27: =IFERROR((E27-D27)*(G27-H27),0) -> 0 | P27: =IFERROR(F27*(K27-G27),0) -> 0 | Q27: =IFERROR(IF(ABS((E27-C27)/C27)>0.2,IF(SUM(N27:O27)<0,ABS(G27-H27)*(ABS(C27-E27)-C27*0.2),0),0),IF(SUM(N27:O27)<0,ABS(G27-H27)*(ABS(C27-E27)-C27*0.2),0)) -> 0 | R27: =IFERROR(K27*C27,0) -> 5874.624 | S27: =IFERROR((D27-E27)*(K27-G27),0) -> 0 | T27: =IFERROR((F27-D27)*(K27-G27),0) -> 0 | U27: =IFERROR((D27-C27)*(K27-H27),0) -> 0 | V27: =IFERROR((E27-D27)*(K27-H27),0) -> 0 | X27: =ROUND(D27*1.2-SUM(Y27,AB27,AE27,AH27,AK27,AN27,AQ27,AT27,AW27,AZ27,BC27,BF27,BI27,BL27,BO27),3) -> 18.685 | Y27: =交易记录!E6 -> 0.265 | Z27: =交易记录!D37 -> 372 | AA27: =IFERROR((Z27-G27)*Y27,0) -> 0 | AB27: =交易记录!E70 -> 0 | AC27: =交易记录!E101 -> 0 | AD27: =IFERROR((AC27-$G27)*AB27,0) -> 0 | AE27: =交易记录!E134 -> 0 | AF27: =交易记录!E165 -> 0 | AG27: =IFERROR((AF27-$G27)*AE27,0) -> 0 | AH27: =交易记录!E198 -> 0 | AI27: =交易记录!E229 -> 0 | AJ27: =IFERROR((AI27-$G27)*AH27,0) -> 0 | AK27: =交易记录!E262 -> 0 | AL27: =交易记录!E293 -> 0 | AM27: =IFERROR((AL27-$G27)*AK27,0) -> 0 | AN27: =交易记录!E326 -> 0 | AO27: =交易记录!E357 -> 0 | AP27: =IFERROR((AO27-$G27)*AN27,0) -> 0 | AQ27: =交易记录!E390 -> 0 | AR27: =交易记录!D421 -> 0 | AS27: =IFERROR((AR27-$G27)*AQ27,0) -> 0 | AT27: =交易记录!E454 -> 0 | AU27: =交易记录!D485 -> 0 | AV27: =IFERROR((AU27-$G27)*AT27,0) -> 0 | AW27: =交易记录!E518 -> 0 | AX27: =交易记录!D549 -> 0 | AY27: =IFERROR((AX27-$G27)*AW27,0) -> 0 | AZ27: =交易记录!E582 -> 0 | BA27: =交易记录!D613 -> 0 | BB27: =IFERROR((BA27-$G27)*AZ27,0) -> 0 | BC27: =交易记录!E646 -> 0 | BD27: =交易记录!D677 -> 0 | BE27: =IFERROR((BD27-$G27)*BC27,0) -> 0 | BF27: =交易记录!E710 -> 0 | BG27: =交易记录!D741 -> 0 | BH27: =IFERROR((BG27-$G27)*BF27,0) -> 0 | BI27: =交易记录!E774 -> 0 | BJ27: =交易记录!D805 -> 0 | BK27: =IFERROR((BJ27-$G27)*BI27,0) -> 0 | BL27: =交易记录!E838 -> 0 | BM27: =交易记录!D869 -> 0 | BN27: =IFERROR((BM27-$G27)*BL27,0) -> 0 | BO27: =交易记录!E902 -> 0 | BP27: =交易记录!D933 -> 0 | BQ27: =IFERROR((BP27-$G27)*BO27,0) -> 0
A28: ='维护-日期'!A$4 -> 46267 | B28: 02:00-03:00 | C28: =D28 -> 14.822 | D28: =ROUND(INDEX(持仓数据!$C$3:$AG$26,MATCH('计算过程-数据汇总'!B28,持仓数据!$B$3:$B$26,0),MATCH('计算过程-数据汇总'!A28,'维护-日期'!$B$2:$AF$2,0)),3) -> 14.822 | E28: =D28*1 -> 14.822 | F28: =持仓数据!D74 -> 0.242 | G28: 372 | H28: 372 | I28: 0 | J28: 0 | K28: =IF(持仓数据!D107="",0,持仓数据!D107) -> 372 | L28: =I28*J28 -> 0 | M28: =IFERROR(C28*G28,0) -> 5513.784 | N28: =IFERROR((D28-C28)*(G28-H28),0) -> 0 | O28: =IFERROR((E28-D28)*(G28-H28),0) -> 0 | P28: =IFERROR(F28*(K28-G28),0) -> 0 | Q28: =IFERROR(IF(ABS((E28-C28)/C28)>0.2,IF(SUM(N28:O28)<0,ABS(G28-H28)*(ABS(C28-E28)-C28*0.2),0),0),IF(SUM(N28:O28)<0,ABS(G28-H28)*(ABS(C28-E28)-C28*0.2),0)) -> 0 | R28: =IFERROR(K28*C28,0) -> 5513.784 | S28: =IFERROR((D28-E28)*(K28-G28),0) -> 0 | T28: =IFERROR((F28-D28)*(K28-G28),0) -> 0 | U28: =IFERROR((D28-C28)*(K28-H28),0) -> 0 | V28: =IFERROR((E28-D28)*(K28-H28),0) -> 0 | X28: =ROUND(D28*1.2-SUM(Y28,AB28,AE28,AH28,AK28,AN28,AQ28,AT28,AW28,AZ28,BC28,BF28,BI28,BL28,BO28),3) -> 17.544 | Y28: =交易记录!E7 -> 0.242 | Z28: =交易记录!D38 -> 372 | AA28: =IFERROR((Z28-G28)*Y28,0) -> 0 | AB28: =交易记录!E71 -> 0 | AC28: =交易记录!E102 -> 0 | AD28: =IFERROR((AC28-$G28)*AB28,0) -> 0 | AE28: =交易记录!E135 -> 0 | AF28: =交易记录!E166 -> 0 | AG28: =IFERROR((AF28-$G28)*AE28,0) -> 0 | AH28: =交易记录!E199 -> 0 | AI28: =交易记录!E230 -> 0 | AJ28: =IFERROR((AI28-$G28)*AH28,0) -> 0 | AK28: =交易记录!E263 -> 0 | AL28: =交易记录!E294 -> 0 | AM28: =IFERROR((AL28-$G28)*AK28,0) -> 0 | AN28: =交易记录!E327 -> 0 | AO28: =交易记录!E358 -> 0 | AP28: =IFERROR((AO28-$G28)*AN28,0) -> 0 | AQ28: =交易记录!E391 -> 0 | AR28: =交易记录!D422 -> 0 | AS28: =IFERROR((AR28-$G28)*AQ28,0) -> 0 | AT28: =交易记录!E455 -> 0 | AU28: =交易记录!D486 -> 0 | AV28: =IFERROR((AU28-$G28)*AT28,0) -> 0 | AW28: =交易记录!E519 -> 0 | AX28: =交易记录!D550 -> 0 | AY28: =IFERROR((AX28-$G28)*AW28,0) -> 0 | AZ28: =交易记录!E583 -> 0 | BA28: =交易记录!D614 -> 0 | BB28: =IFERROR((BA28-$G28)*AZ28,0) -> 0 | BC28: =交易记录!E647 -> 0 | BD28: =交易记录!D678 -> 0 | BE28: =IFERROR((BD28-$G28)*BC28,0) -> 0 | BF28: =交易记录!E711 -> 0 | BG28: =交易记录!D742 -> 0 | BH28: =IFERROR((BG28-$G28)*BF28,0) -> 0 | BI28: =交易记录!E775 -> 0 | BJ28: =交易记录!D806 -> 0 | BK28: =IFERROR((BJ28-$G28)*BI28,0) -> 0 | BL28: =交易记录!E839 -> 0 | BM28: =交易记录!D870 -> 0 | BN28: =IFERROR((BM28-$G28)*BL28,0) -> 0 | BO28: =交易记录!E903 -> 0 | BP28: =交易记录!D934 -> 0 | BQ28: =IFERROR((BP28-$G28)*BO28,0) -> 0
